Workbook
Name B111D111: Fathy!$C$111:$C$111
Name F100H100: Fathy!$G$100:$G$100
Name F101H101: Fathy!$G$101:$G$101
Name F102H102: Fathy!$G$102:$G$102
Name F98H98: Fathy!$G$98:$G$98
Name F99H99: Fathy!$G$99:$G$99
Name H110J110: Fathy!$I$110:$I$110
Name H111J111: Fathy!$I$111:$I$111
Name L100B101: Fathy!$A$98:$A$109
Name L101B102: Fathy!$A$98:$A$109
Name L102B103: Fathy!$A$98:$A$109
Name L104B105: Fathy!$A$98:$A$109
Name L99B100: Fathy!$A$98:$A$109

Sheet Main 
A1: Reviewer / Member | B1: Paper's DOI | C1: Title | D1: Publication Year | E1: Publisher | F1: paper URL | G1: Technology | H1: Included or Excluded | I1: Reason for inclusivity | J1: Problem | K1: Solution | L1: Main Tags | M1: Another Tags | N1: Reviewer Notes / Original Slot | O1: Systematic Scope Status | P1: Numbering for ref
A2: David | B2: 10.1016/j.bcp.2025.116272 | C2: A quantitative assessment of EOG eye tracking during free viewing in sighted and in congenitally blind | D2: 2025 | E2: Elsevier | F2: https://www.sciencedirect.com/science/article/pii/S0006899325003555?via%3Dihub | G2: Electrooculography (EOG) Video-Based Eye Tracking SMI Eye-Tracking Glasses Smarting Mobile EEG g.HIamp Amplifier BioSemi EEG vEOG / hEOG Blink Detection Saccade Detection The vOICe | H2: Included | I2: Meets inclusion criteria for assistive spatial navigation, tactile feedback, or obstacle detection. | J2: Limited exploration of EOG in naturalistic/free-viewing conditions Video-based tracking can fail in blind individuals due to pupil abnormalities or eyelid control Need to detect eye movements without visual fixation | K2: EOG-based detection of blinks and saccades Comparison with video-based eye tracking Testing under light, darkness, eyes-closed, and congenital blindness Demonstrated that EOG can detect eye movements in blind participants | L2: Tactile & Sensory Substitution Systems (TSSS) | M2: Tactile-Actuation, Corridor-Navigation, Human-Factors-Usability, Wearable-Embedded | N2: Original assignment for David (Row 2) | O2: Primary SLR Target | P2: REF-001
A3: David | B3: 10.1016/j.neuroimage.2025.121652 | C3: Long-term visual-to-tactile stimulation induces functional reorganization of thalamic pathways to achieve visual perception | D3: 2025 | E3: Elsevier | F3: https://www.sciencedirect.com/science/article/pii/S105381192500655X?via%3Dihub | G3: Sensory Substitution Device (SSD) Visual-to-Tactile Conversion Tactile Stimulation Resting-State fMRI Functional Connectivity Analysis Thalamic/Occipital Brain Imaging | H3: Included | I3: Directly relevant: six-month training of blind children with a camera-to-2D-vibrotactile SSD, with resting-state fMRI evidence of thalamo-occipital reorganisation linked to tactile identification performance. | J3: Limited understanding of how long-term tactile sensory substitution produces visual perception. Unclear how the brain reorganizes its pathways during prolonged SSD use. | K3: Long-term visual-to-tactile stimulation/training. Investigation of changes in thalamic–occipital connectivity to understand the neural mechanism. | L3: Tactile & Sensory Substitution Systems (TSSS) | M3: Tactile-Actuation, Corridor-Navigation, Human-Factors-Usability | N3: Original assignment for David (Row 3) | O3: Primary SLR Target | P3: REF-002
A4: David | B4: 10.1016/j.neuroimage.2021.118029 | C4: Topographic maps and neural tuning for sensory substitution dimensions learned in adulthood in a congenital blind subject | D4: 2021 | E4: Elsevier | F4: https://www.sciencedirect.com/science/article/pii/S1053811921003062?via%3Dihub | G4: Auditory Sensory Substitution Device 2D Auditory Soundscape Pitch Encoding Temporal Encoding Population Receptive Field Mapping fMRI | H4: Included | I4: Neuroimaging evidence that a congenitally blind adult trained on a visual-to-auditory SSD forms topographic cortical maps of the learned 2D space; supports learnability of sensory substitution in adulthood. | J4: How the adult brain represents newly learned sensory dimensions in a person who is congenitally blind. | K4: Convert spatial information into auditory dimensions. Train the participant to interpret the auditory representation. Analyze the resulting neural maps and tuning. | L4: Tactile & Sensory Substitution Systems (TSSS) | M4: Tactile-Actuation, Human-Factors-Usability | N4: Original assignment for David (Row 4) | O4: Primary SLR Target | P4: REF-003
A5: David | B5: 10.1016/j.neuroimage.2024.120621 | C5: Visual Mental Imagery and Neural Dynamics of Sensory Substitution in the Blindfolded Subjects | D5: 2024 | E5: Elsevier | F5: https://www.sciencedirect.com/science/article/pii/S1053811924001162?via%3Dihub | G5: Auditory Sensory Substitution Visual-to-Auditory Encoding Soundscape Stimuli Functional MRI Dynamic Causal Modeling (DCM) Visual Mental Imagery | H5: Included | I5: EEG study of the neural mechanism and learning curve of visual-to-auditory sensory substitution (vOICe soundscapes) in blindfolded sighted subjects; informs SSD training and perception. | J5: How sensory-substitution information is processed by the brain. Whether auditory sensory substitution can engage visual mental imagery. | K5: Train subjects to interpret auditory representations of visual shapes. Use neuroimaging and DCM to analyze the resulting brain-network dynamics. | L5: Tactile & Sensory Substitution Systems (TSSS) | M5: Tactile-Actuation, AI-Object-Detection, Human-Factors-Usability | N5: Original assignment for David (Row 5) | O5: Primary SLR Target | P5: REF-004
A6: David | B6: 10.1177/0145482X19842491 | C6: A Haptic Navigation Aid for Individuals with Visual Impairments: Indoor and Outdoor Feasibility Evaluations of the LaserNavigator | D6: 2019 | E6: SAGE Publications | F6: https://journals.sagepub.com/doi/10.1177/0145482X19842491 | G6: Laser Rangefinder Haptic Feedback Vibrating Actuator Handheld Device Virtual White Cane Variable Virtual Cane Length | H6: Included | I6: Handheld laser-ranging electronic travel aid with haptic (vibration) feedback, evaluated indoors and outdoors with blind users; a direct haptic navigation competitor without AI vision. | J6: Conventional white canes have a limited detection range. | K6: Use a laser rangefinder to detect objects beyond normal cane range. Convert measured distance into haptic feedback. | L6: Tactile & Sensory Substitution Systems (TSSS) | M6: Tactile-Actuation, Depth-Sensing, AI-Object-Detection, Corridor-Navigation, Human-Factors-Usability | N6: Original assignment for David (Row 6) | O6: Primary SLR Target | P6: REF-005
A7: David | B7: 10.5220/0006617505550562 | C7: Wearable RGB Camera-based Navigation System for the Visually Impaired | D7: 2018 | E7: SciTePress | F7: https://www.scitepress.org/PublishedPapers/2018/66175/ | G7: Laptop in backpack (Intel Core i7-4700MQ, 8 GB RAM; MATLAB) | H7: Excluded | I7: Published by SciTePress | J7: Accuracy drops with occlusion, illumination change between training/testing and sudden camera movements; needs optimisation for real-time devices, cluttered paths, and detection of holes, stairs and obstacles. | K7: Temporal video alignment via spatial pyramid matching locates the user on a training video; SURF matching plus optimal RANSAC estimate relative camera pose mapped to five instructions every 1 s; tested offline on 6 indoor and 6 outdoor path pairs against human-voted references. | L7: Edge Computer Vision & 3D Spatial Perception (CV-3D) | M7: Corridor-Navigation, Human-Factors-Usability, Wearable-Embedded | N7: Original assignment for David (Row 7) | O7: Screened / Excluded | P7: REF-006
A8: David | B8: 10.1609/aaai.v37i2.25233 | C8: BEVDepth: Acquisition of Reliable Depth for Multi-View 3D Object Detection | D8: 2023 | E8: AAAI | F8: https://ojs.aaai.org/index.php/AAAI/article/view/25233 | G8: Tactile & Sensory Substitution Hardware | H8: Excluded | I8: Because it falls in a different feild of study and is published by AAAI | J8: Accurate distance estimation and low-latency obstacle identification under embedded edge hardware constraints. | K8: An embedded computer vision pipeline integrating depth sensing with neural object detection for hazard alerts. | L8: Edge Computer Vision & 3D Spatial Perception (CV-3D) | M8: Tactile-Actuation, Depth-Sensing, AI-Object-Detection, Wearable-Embedded | N8: Original assignment for David (Row 8) | O8: Screened / Excluded | P8: REF-007
A9: David | B9: 10.1109/EMBC.2013.6611022 | C9: Electrotactile vision substitution for 3D trajectory following | D9: 2013 | E9: IEEE | F9: https://ieeexplore.ieee.org/document/6611022 | G9: Tactile & Sensory Substitution Hardware | H9: Excluded | I9: Published in 2013 and The linked IEEE document does not appear to correspond to the assistive-vision/navigation research needed for your review | J9: High cognitive latency and spatial distortion when conveying complex visual scenes across skin-touch feedback. | K9: A wearable haptic/tactile feedback matrix encoding spatial clearance and obstacle proximity via cutaneous cues. | L9: Tactile & Sensory Substitution Systems (TSSS) | M9: Tactile-Actuation, Corridor-Navigation, Human-Factors-Usability, Wearable-Embedded | N9: Original assignment for David (Row 9) | O9: Screened / Excluded | P9: REF-008
A10: David | B10: 10.1109/EIT51626.2021.9491913 | C10: Visually Impaired Indoor Navigation using YOLO Based Object Recognition, Monocular Depth Estimation and Binaural Sounds | D10: 2021 | E10: IEEE | F10: https://ieeexplore.ieee.org/document/9491913 | G10: Monocular RGB Camera Deep Learning ResNet-50 Backbone Encoder–Decoder Network YOLOv8 Object Detection Monocular Depth Estimation Object Distance Estimation D-Far250 Dataset KITTI Dataset Binaural/Spatial Audio HRTF | H10: Excluded | I10: restricted access | J10: Difficulty detecting objects and understanding their distance and spatial position during indoor navigation. | K10: YOLO detects objects. Monocular depth estimation estimates object distance. Spatial information is converted into binaural audio. Audio provides directional and distance information to the user. | L10: Edge Computer Vision & 3D Spatial Perception (CV-3D) | M10: Depth-Sensing, AI-Object-Detection, Corridor-Navigation, Human-Factors-Usability | N10: Original assignment for David (Row 10) | O10: Screened / Excluded | P10: REF-009
A11: David | B11: 10.1109/TITS.2022.3161141 | C11: Trans4Trans: Efficient Transformer for Transparent Object and Semantic Scene Segmentation in Real-World Navigation Assistance | D11: 2021 | E11: arXiv | F11: https://ieeexplore.ieee.org/document/9743965 | G11: RGB-D Camera Portable GPU Trans4Trans Transformer Transformer Parsing Module (TPM) Semantic Segmentation Transparent Object Segmentation Depth Information Bone-Conduction Earphone | H11: Excluded | I11: restricted access | J11: Transparent objects such as glass doors and glass walls can be incorrectly interpreted as free/walkable space. | K11: Detect transparent objects separately. Combine transparent-object segmentation with semantic segmentation and depth information. Provide navigation feedback to the visually impaired user. | L11: Edge Computer Vision & 3D Spatial Perception (CV-3D) | M11: Depth-Sensing, AI-Object-Detection, Corridor-Navigation, Human-Factors-Usability, Wearable-Embedded | N11: Original assignment for David (Row 11) | O11: Screened / Excluded | P11: REF-010
A12: David | B12: 10.1109/TOH.2021.3138590 | C12: In-Device Feedback in Immersive Head-Mounted Displays for Distance Perception During Teleoperation of Unmanned Ground Vehicles | D12: 2022 | E12: arXiv | F12: https://ieeexplore.ieee.org/document/9664257 | G12: Tactile & Sensory Substitution Hardware | H12: Excluded | I12: Different feild of study (The actual application is remote control of unmanned ground vehicles0 | J12: Sensory substitution bottlenecks and spatial perception limitations in visual impairment assistance. | K12: A multi-modal assistive navigation framework translating real-time sensory data into intuitive non-visual guidance. | L12: Tactile & Sensory Substitution Systems (TSSS) | M12: Tactile-Actuation, Depth-Sensing, Corridor-Navigation, Wearable-Embedded | N12: Original assignment for David (Row 12) | O12: Screened / Excluded | P12: REF-011
A13: David | B13: 10.48550/arXiv.2201.04453 | C13: Obstacle Avoidance for Blind People Using a 3D Camera and a Haptic Feedback Sleeve | D13: 2022 | E13: arXiv / CoRR | F13: https://arxiv.org/abs/2201.04453 | G13: Intel RealSense D415 3D Camera 3D Point Cloud Depth Mapping AAEON Up Board 5×5 Haptic Feedback Sleeve Vibration Motor Array Spatial Depth-to-Haptic Mapping 3D-Printed Glasses | H13: Included | I13: Meets inclusion criteria for assistive spatial navigation, tactile feedback, or obstacle detection. | J13: Limited obstacle detection range using conventional aids. Difficulty providing multidimensional information about obstacles. Some existing approaches depend on lighting conditions. | K13: Capture 3D depth information using the RealSense camera. Convert the depth map into a 5×5 spatial representation. Map each region to a corresponding vibration motor. Use vibration intensity to communicate obstacle distance. | L13: Edge Computer Vision & 3D Spatial Perception (CV-3D) | M13: Tactile-Actuation, Depth-Sensing, Corridor-Navigation, Human-Factors-Usability, Wearable-Embedded | N13: Original assignment for David (Row 13) | O13: Primary SLR Target | P13: REF-012
... A29: Taha | B29: 10.1109/JAS.2021.1004084 | C29: An RGB-D Camera Based Visual Positioning System for Assistive Navigation by a Robotic Navigation Aid | D29: 2021 | E29: IEEE | F29: https://www.ieee-jas.net/article/doi/10.1109/JAS.2021.1004084?pageType=en | G29: RGB-D Camera IMU Visual-Inertial Odometry (VIO) 6-DOF Pose Estimation Particle Filter Localization Indoor CAD/Floor Plans Path Planning & Obstacle Avoidance Real-time processing | H29: Included | I29: Because it focuses on assistiv navigation for impaired users and combine computer vision with RGB and real time navigation | J29: blind people need reliable navigation assistance in large indoor environments Existing mobility tools such as white canes and guide dogs do not provide electronic localization/navigation information | K29: The paper develops a real-time visual positioning system for a robotic navigation aid. It combines an RGB-D camera + IMU to estimate the device's 6-DOF pose, then uses a particle filter and indoor CAD floor-plan information to reduce localization error and support wayfinding | L29: Ground Segmentation & Safe Path Navigation (GS-PN) | M29: Depth-Sensing, AI-Object-Detection, Corridor-Navigation, Human-Factors-Usability | N29: Original assignment for Taha (Row 29) | O29: Primary SLR Target | P29: REF-028
A30: Taha | B30: N/A | C30: [Reserved Template Slot / Excluded] | D30: N/A | E30: N/A | F30: N/A | G30: N/A | H30: Excluded | I30: Empty placeholder slot in original allocation template. | J30: N/A | K30: N/A | L30: Excluded (Template Slot) | N30: Reserved slot for Taha (Empty in original) | O30: Template Slot | P30: REF-SLOT-030
A31: Taha | B31: 10.5220/0006617505550562 | C31: Wearable RGB Camera-based Navigation System for the Visually Impaired | D31: 2018 | E31: SciTePress | F31: https://www.scitepress.org/PublishedPapers/2018/66175/ | G31: X | H31: Excluded | I31: Published by SciTePress | J31: X | K31: X | L31: Edge Computer Vision & 3D Spatial Perception (CV-3D) | M31: Corridor-Navigation, Human-Factors-Usability, Wearable-Embedded | N31: Original assignment for Taha (Row 31) | O31: Screened / Excluded | P31: REF-029
A32: Taha | B32: 10.1177/20552076251408522 | C32: Sensory-driven micro-interventions for improved health and wellbeing | D32: 2025 | E32: Sage | F32: https://journals.sagepub.com/home/dhj | G32: AI / Machine Learning IoT Wearable sensors Sensory devices & interfaces Real-time data collection and processing Sensory substitution Vibrotactile / haptic feedback Smartphones and connected devices Embedded sensors | H32: Included | I32: included because paper support sensory substituation and hapitic feedback concept of super Brain it discusses technologies that convert environmental/visual information into tactile feedback for visually impaired users | J32: sensory technologies work separately there no simple system for continuously monitoring sensory changes and providing personalized help when needed | K32: The paper proposes using AI IoT wearable sensors and sensory devices to monitor sensory changes and provide personalized sensory training | L32: Tactile & Sensory Substitution Systems (TSSS) | M32: Tactile-Actuation, AI-Object-Detection, Human-Factors-Usability, Wearable-Embedded | N32: Original assignment for Taha (Row 32) | O32: Primary SLR Target | P32: REF-030
A33: Taha | B33: 10.1007/s42486-023-00136-7 | C33: A smart obstacle avoiding technology based on depth camera for blind and visually impaired people | D33: 2023 | E33: Springer Nature | F33: https://link.springer.com/article/10.1007/s42486-023-00136-7? | G33: Depth/RGB-D Camera — Intel RealSense D435i 3D Point Cloud L-PointPillars Deep Learning / Neural Network Depthwise Separable Convolution Attention Mechanism NVIDIA Jetson Xavier NX PyTorch + Python Text-to-Speech (TTS) Audio Feedback | H33: Included | I33: Included because it uses a depth camera and AI-based obstacle detection to help blind and visually impaired people navigate safely outdoors | J33: impaired people difficult detecting and avoiding obstacles when traveling outdoors. Existing assistive devices have limited detection range and limited computing power | K33: The paper proposes a wearable system that uses a depth camera and L-PointPillars to detect obstacles in real time and gives audio information about the obstacle and its distance | L33: Edge Computer Vision & 3D Spatial Perception (CV-3D) | M33: Depth-Sensing, AI-Object-Detection, Corridor-Navigation, Human-Factors-Usability, Wearable-Embedded | N33: Original assignment for Taha (Row 33) | O33: Primary SLR Target | P33: REF-031
A34: Taha | B34: 10.1016/j.eswa.2023.121065 | C34: A data fusion framework based on heterogeneous information network embedding for trigger-action programming in IoT | D34: 2023 | E34: Elsevier | F34: https://www.sciencedirect.com/science/article/abs/pii/S0957417423015671?via%3Dihub | G34: IoT Artificial Intelligence of Things (NLP) Heterogeneous Information Network HIN Embedding Metagraph-guided Random Walk Skip-gram Multi-label Classification | H34: Included | I34: there are too many trigger-action combinations that is difficult and time-consuming for users to create IoT recipes manually | J34: Limited environmental awareness for visually impaired individuals; high cognitive load from unsimplified sensory streams; lack of intuitive distance perception. | K34: The paper proposes TAPFuser an IoT framework that uses NLP and HIN embedding to understand natural-language requests and automatically recommend suitable trigger-action recipe | L34: Cognitive Ergonomics & Blind Usability (CE-BU) | M34: Depth-Sensing, Human-Factors-Usability | N34: Original assignment for Taha (Row 34) | O34: Primary SLR Target | P34: REF-032
A35: Taha | B35: 10.1038/s41928-023-01074-z | C35: A skin-integrated multimodal haptic interface for immersive tactile feedback | D35: 2023 | E35: Nature | F35: https://doi.org/10.1038/s41928-023-01074-z | G35: RGB Camera, Raspberry Pi & ESP32, Electrotactile Array, Classical CV & Feature Extraction, Electrotactile Array | H35: Included | I35: Wearable skin-integrated tactile actuator arrays (mechanical, electrotactile, thermal) for VR; relevant to the tactile display layer, though not designed or tested for VI navigation. | J35: X | K35: X | L35: Tactile & Sensory Substitution Systems (TSSS) | M35: Tactile-Actuation, Corridor-Navigation, Wearable-Embedded | N35: Original assignment for Taha (Row 35) | O35: Primary SLR Target | P35: REF-033
A36: Taha | B36: 10.1002/aisy.70450 | C36: Enhanced Monocular Depth Estimation Using ResNet Backbone and Multiscale Feature Decoding for Precise Object Distance Measurement | D36: 2026 | E36: Wiley | F36: https://www.nature.com/articles/s41928-023-01074-z | G36: Monocular RGB Camera Deep Learning ResNet-based Encoder–Decoder Multiscale Feature Decoding YOLOv8 Object Detection Monocular Depth Estimation Object Distance Estimation D-Far250 Dataset KITTI Dataset | H36: Included | I36: because it uses deep learning and object detection and and monocular depth estimation to detect objects and measure their distance and that support obstacle detection and navigation in Super Brain | J36: Traditional depth systems often need expensive sensors such as LiDAR or stereo cameras while monocular systems can have difficulty estimating accurate distances especially for far objects. | K36: The paper proposes a deep-learning system that uses a single RGB camera with a ResNet-based model and YOLOv8 to estimate object depth and distance without LiDAR or stereo cameras | L36: Edge Computer Vision & 3D Spatial Perception (CV-3D) | M36: Depth-Sensing, AI-Object-Detection, Corridor-Navigation, Human-Factors-Usability | N36: Original assignment for Taha (Row 36) | O36: Primary SLR Target | P36: REF-034
A37: Taha | B37: https://doi.org/10.1016/j.patrec.2019.03.008 | C37: Enhancing perception for the visually impaired with deep learning techniques and low-cost wearable sensors | D37: 2020 | E37: Elsevier | F37: https://www.sciencedirect.com/science/article/abs/pii/S0167865519300881?via%3Dihub | G37: * Shirt-pocket miniature wireless RGB camera * smartphone , smart watch * Monocular Depth Estimation --> ResNet-50 backbone * Urban Object Detection:---> CNN detector : 7 urban obstacle classes * Spatial Discretization:---> Bins 3D space in front of the user into 9 sectors * Continuous 3-level intensity haptic feedback | H37: Included | I37: Deeplearning Techniques for Enhancing Perception for Visuall impaired | J37: * visually impaired people face the outdoor environment and connot detect teh distance of the obstacles * ETAs : Travel aids ---> relying on RGB camera , LIDAR are heavy , big , fail in sunlight , expensive | K37: * lightweigh , low cost , replace with physical depth sensors * monocular depth , couples with object dedector * descretizes 3d space , delivers continuous 3 intensity habtic vibration | L37: Edge Computer Vision & 3D Spatial Perception (CV-3D) | M37: Tactile-Actuation, Depth-Sensing, AI-Object-Detection, Human-Factors-Usability, Wearable-Embedded | N37: Original assignment for Taha (Row 37) | O37: Primary SLR Target | P37: REF-035
A38: Abdallah | B38: https://doi.org/10.1016/j.neunet.2023.12.042 | C38: Bidirectional visual-tactile cross-modal generation using latent feature space flow model | D38: 2023 | E38: Elsevier | F38: https://www.sciencedirect.com/science/article/pii/S0893608023007499?via%3Dihub | G38: * Decoupled visual and tactile Variational Autoencoders * Conditional Flow Model * Contrastive Supervision: InfoNCE contrastive loss (CLIP-style) * Sensory Modalities & Datasets: Evaluated on Touch2Go and LMT multimodal datasets * Quantitative Results: Reaches SSIM | H38: Included | I38: artificial sensory substitution by translating 2D visual inputs into tactile representations | J38: * scale discrepancy ---> global scene geometry vs. localized tactile contact * heterogeneous gap ---> pixels vs. mechanical deformation/vibration * Prior cross-modal methods were strictly unidirectional or required training two separate, unstable GAN networks , leading to inconsistent representations and heavy computational cost. | K38: * A unified generative architecture that maps visual features and tactile signals into separate VAE latent spaces, connected by an invertible conditional flow model that bidirectionally translates visual scenes into realistic tactile representations with high semantic fidelity. | L38: Tactile & Sensory Substitution Systems (TSSS) | M38: Tactile-Actuation, AI-Object-Detection | N38: Original assignment for Abdallah (Row 38) | O38: Primary SLR Target | P38: REF-036
A39: Abdallah | B39: https://ieeexplore.ieee.org/document/5165018 | C39: Wearable Obstacle Avoidance Electronic Travel Aids for Blind: A Survey | D39: 2010 | E39: IEEE | F39: https://ieeexplore.ieee.org/document/5165018 | G39: ------------------ | H39: Excluded | I39: Survey | J39: ------------------ | K39: ------------------ | L39: Ground Segmentation & Safe Path Navigation (GS-PN) | M39: Corridor-Navigation, Human-Factors-Usability, Wearable-Embedded | N39: Original assignment for Abdallah (Row 39) | O39: Screened / Excluded | P39: REF-037
A40: Abdallah | B40: https://doi.org/10.1007/s11042-021-11287-z | C40: Design and development of an indoor navigation system using denoising autoencoder based convolutional neural network for visually impaired people | D40: 2021 | E40: Springer | F40: https://link.springer.com/article/10.1007/s11042-021-11287-z | G40: * DAECNN Architecture * Multi-Angle Visual Localization --> Classifies 12 discrete viewing angles * Evaluation & Dataset---> Trained on 11,190 indoor frames | H40: Included | I40: Vision-Based Indoor Navigation & Visual Localization | J40: * GPS satellite signals cannot penetrate indoor environments * Alternative indoor positioning technologies ----> expensive, power consumpsion * Camera images captured while walking suffer from heavy motion blur, camera shaking, | K40: * Implements the DAECNN pipeline ---> enoising autoencoder to strip noise and motion blur * user positioning accuracy without external infrastructure | L40: Edge Computer Vision & 3D Spatial Perception (CV-3D) | M40: AI-Object-Detection, Corridor-Navigation, Human-Factors-Usability | N40: Original assignment for Abdallah (Row 40) | O40: Primary SLR Target | P40: REF-038
A41: Abdallah | B41: https://doi.org/10.1007/s11042-023-16355-0 | C41: Development of a visual to audio and tactile substitution system for mobility and orientation of visually impaired people: a review | D41: 2023 | E41: Springer | F41: https://link.springer.com/article/10.1007/s11042-023-16355-0 | G41: * Sensory Substitution ---> visual-to-audio , visual-to-tactile * Reviews RGB cameras, depth sensors, ultrasonic transducers, and deep learning object/obstacle recognition models. | H41: Included | I41: Comprehensive Review of Visual-to-Tactile & Audio Sensory Substitution | J41: * white canes cannot detect elevated, head-height, or distant obstacles. * Existing assistive systems are non-adaptable, expensive, and heavily | K41: * prioritizing low-cost wearable tactile arrays that preserve hearing , simplify visual scene features into intuitive haptic patterns, and utilize structured user training protocols. | L41: Tactile & Sensory Substitution Systems (TSSS) | M41: Tactile-Actuation, Depth-Sensing, AI-Object-Detection, Human-Factors-Usability, Wearable-Embedded | N41: Original assignment for Abdallah (Row 41) | O41: Primary SLR Target | P41: REF-039
A42: Abdallah | B42: https://doi.org/10.1049/ell2.70570 | C42: A Portable Intelligent Navigation System Based on Embedded Hybrid Computing for Visually Impaired People | D42: 2026 | E42: Wiley | F42: https://ietresearch.onlinelibrary.wiley.com/doi/10.1049/ell2.70570 | G42: * Multi-core STM32MP157F system * Hybrid Edge-Cloud Architecture * natural-language voice feedback for destination guidance and traffic | H42: Included | I42: Embedded System Design & Hybrid Vision-Tactile Navigation | J42: * risks at street intersections, pedestrian crossings, and outdoor sidewalks * Running deep visual-language models entirely on-device causes overheating * battery exhaustion , lag *cloud services risks complete failure in poor network coverage | K42: * A layered, hybrid embedded architecture where a multi-core STM32 * manages local low-latency sensor * high-level visual scene interpretation to cloud vision-language models | L42: Ground Segmentation & Safe Path Navigation (GS-PN) | M42: Tactile-Actuation, AI-Object-Detection, Corridor-Navigation, Human-Factors-Usability, Wearable-Embedded | N42: Original assignment for Abdallah (Row 42) | O42: Primary SLR Target | P42: REF-040
... A64: Hend | B64: 10.1177/20556683251316305 | C64: The development of a wearable goggle echolocation device to support people who are visually impaired with unhindered and unaided movement | D64: 2025 | E64: Sage | F64: https://journals.sagepub.com/doi/10.1177/20556683251316305 | G64: The wearable echolocation device was developed using three ultrasonic sensors, one placed in the right, left, and middle of the goggle with each connected to a buzzer | H64: Included | I64: Low-cost wearable goggle with three ultrasonic sensors and audio cues plus audible compass for VI obstacle avoidance; tested with VI/blind users. | J64: Cannot detect drop-offs such as gutters or valleys; soft fabrics and foams distort ultrasonic ranging; small sample; goggle fabrication not described. | K64: Community-engaged design; three HC-SR04 ultrasonic sensors (left/centre/right) on a VR goggle shell, Arduino Nano, ISD voice chip playing 8 recorded sounds, HMC5883L audible compass; five indoor tasks repeated 10 times by VI participants. | L64: Ground Segmentation & Safe Path Navigation (GS-PN) | M64: Depth-Sensing, Corridor-Navigation, Human-Factors-Usability, Wearable-Embedded | N64: Original assignment for Hend (Row 64) | O64: Primary SLR Target | P64: REF-062
A65: Hend | B65: N/A | C65: EMPOWERING VISUALLY IMPAIRED INDIVIDUALS WITH HOLISTIC ASSISTANCE USING REAL-TIME SPATIAL AWARENESS SYSTEM | D65: 2024 | E65: 2024 | F65: N/A | G65: Jetson Orin Nano | H65: Excluded | I65: unknown | J65: NR (results and conclusion chapters not included in the 24-page excerpt) | K65: Layered architecture: ArUco markers for place recognition and node-map path planning, YOLOv8 detection/tracking, depth-based object localisation and obstacle avoidance, TTS/STT interface; evaluated in environments simulating real-world scenarios. | L65: Edge Computer Vision & 3D Spatial Perception (CV-3D) | M65: Depth-Sensing, AI-Object-Detection, Corridor-Navigation, Human-Factors-Usability, Wearable-Embedded | N65: Original assignment for Hend (Row 65) | O65: Screened / Excluded | P65: REF-063
A66: Hend | B66: N/A | C66: Computer Vision for Assistive Technologies: Enhancing Environmental Perception for the Visually Impaired | D66: 45778 | E66: New York University (ProQuest) | F66: N/A | G66: Nvidia Jetson Xavier NX (backpack); ESP32S3 + smartphone for ChatMap | H66: Excluded | I66: unknown | J66: NR (limitations sections not included in the 24-page excerpt) | K66: Monocular wearable system with resolution-adaptive YOLO and trajectory estimation; vision-language models anchored in scene graphs; CORA and EMBOSR robotic reasoning models; evaluated on KITTI, Visual7W, LVSQA, SQA3D and own datasets. | L66: Edge Computer Vision & 3D Spatial Perception (CV-3D) | M66: AI-Object-Detection, Human-Factors-Usability, Wearable-Embedded | N66: Original assignment for Hend (Row 66) | O66: Screened / Excluded | P66: REF-064
A67: Hend | B67: https://doi.org/10.1016/j.heliyon.2024.e31825 | C67: A comprehensive review of navigation systems for visually impaired individuals | D67: 2024 | E67: heliyon | F67: https://www.cell.com/heliyon/fulltext/S2405-8440(24)07856-3?_returnURL=https%3A%2F%2Flinkinghub.elsevier.com%2Fretrieve%2Fpii%2FS2405844024078563%3Fshowall%3Dtrue | G67: RGB Camera, Raspberry Pi & ESP32, Vibrotactile (ERM/LRA), Visual SLAM & Tracking, Vibrotactile (ERM/LRA) | H67: Excluded | I67: unknown | J67: Limited environmental awareness for visually impaired individuals; high cognitive load from unsimplified sensory streams; lack of intuitive distance perception. | K67: 8x8 (64) Vibrotactile (ERM/LRA) display placed on Torso / Vest using Visual SLAM & Tracking. | L67: Tactile & Sensory Substitution Systems (TSSS) | M67: Tactile-Actuation, Depth-Sensing, Corridor-Navigation, Human-Factors-Usability, Wearable-Embedded | N67: Original assignment for Hend (Row 67) | O67: Screened / Excluded | P67: REF-065
A68: Hend | B68: 1905-07-17 00:00:00 | C68: Recruitment of Occipital Cortex during Sensory Substitution Training Linked to Subjective Experience of Seeing in People with Blindness | D68: 40765 | E68: plos one | F68: https://doi.org/1905-07-17 00:00:00 | G68: Tactile & Sensory Substitution Hardware | H68: Excluded | I68: unknown | J68: Sensory substitution bottlenecks and spatial perception limitations in visual impairment assistance. | K68: A multi-modal assistive navigation framework translating real-time sensory data into intuitive non-visual guidance. | L68: Tactile & Sensory Substitution Systems (TSSS) | M68: Tactile-Actuation, Corridor-Navigation, Human-Factors-Usability | N68: Original assignment for Hend (Row 68) | O68: Screened / Excluded | P68: REF-066
A69: Hend | B69: N/A | C69: [Reserved Template Slot / Excluded] | D69: N/A | E69: N/A | F69: N/A | G69: N/A | H69: Excluded | I69: Empty placeholder slot in original allocation template. | J69: N/A | K69: N/A | L69: Excluded (Template Slot) | N69: Reserved slot for Hend (Empty in original) | O69: Template Slot | P69: REF-SLOT-069
A70: Hend | B70: N/A | C70: [Reserved Template Slot / Excluded] | D70: N/A | E70: N/A | F70: N/A | G70: N/A | H70: Excluded | I70: Empty placeholder slot in original allocation template. | J70: N/A | K70: N/A | L70: Excluded (Template Slot) | N70: Reserved slot for Hend (Empty in original) | O70: Template Slot | P70: REF-SLOT-070
A71: Hend | B71: N/A | C71: [Reserved Template Slot / Excluded] | D71: N/A | E71: N/A | F71: N/A | G71: N/A | H71: Excluded | I71: Empty placeholder slot in original allocation template. | J71: N/A | K71: N/A | L71: Excluded (Template Slot) | N71: Reserved slot for Hend (Empty in original) | O71: Template Slot | P71: REF-SLOT-071
A72: Hend | B72: N/A | C72: [Reserved Template Slot / Excluded] | D72: N/A | E72: N/A | F72: N/A | G72: N/A | H72: Excluded | I72: Empty placeholder slot in original allocation template. | J72: N/A | K72: N/A | L72: Excluded (Template Slot) | N72: Reserved slot for Hend (Empty in original) | O72: Template Slot | P72: REF-SLOT-072
A73: Hend | B73: 10.1007/s12559-026-10547-0 | C73: Multi-modal Zebra Crossing Detection Framework for Visually Impaired Navigation | D73: 2026 | E73: Springer | F73: https://link.springer.com/article/10.1007/s12559-026-10547-0 | G73: YOLOv11 - Hough Line Transform (HLT) - Haze U-Net + LeNet-MFCN - CNN + Cross-Attention - Text-to-Speech (TTS) | H73: Included | I73: The AI-powered navigation system detects pedestrian crossings, traffic signals, and obstacles, assisting the blind and visually impaired. This is linked to the "Super Brain" initiative, which focuses on technologies that ensure highly safe navigation. | J73: Blind individuals face challenges such as the high cost of assistive technologies, limited datasets, overfitting, and poor detection in low-light conditions, fog, and complex traffic situations. | K73: MZCDFVIN + YOLOv11 + HLT + CNN + Haze U-Net + LeNet + SROA for real-time detection and navigation assistance. | L73: Ground Segmentation & Safe Path Navigation (GS-PN) | M73: AI-Object-Detection, Corridor-Navigation, Human-Factors-Usability | N73: Original assignment for Hend (Row 73) | O73: Primary SLR Target | P73: REF-067
A74: Mostafa | B74: 10.1007/s12193-025-00463-2 | C74: Haptic and auditory cues: a study on independent navigation for visually impaired individuals | D74: 2025 | E74: Springer | F74: https://link.springer.com/article/10.1007/s12193-025-00463-2 | G74: Intel RealSense D435i stereo vision camera - Depth-map processing & obstacle detection - Odroid-N2 single-board computer - Wearable haptic belt with - 22 vibrating actuators - Auditory feedback / speakers - Bluetooth | H74: Included | I74: Paper is developing a wearable device that utilizes haptic and auditory signals to help the blind and visually impaired move around freely. This initiative is linked to the Super Brain project, as it focuses on leveraging technology to assist individuals with visual impairments. | J74: Current assistive navigation systems struggle to convert visual information into tactile or auditory information in a way that is easy to understand. | K74: Stereo vision + depth processing + haptic belt + auditory feedback + user-controlled operating modes. | L74: Tactile & Sensory Substitution Systems (TSSS) | M74: Tactile-Actuation, Depth-Sensing, Corridor-Navigation, Human-Factors-Usability, Wearable-Embedded | N74: Original assignment for Mostafa (Row 74) | O74: Primary SLR Target | P74: REF-068
A75: Mostafa | B75: 10.1007/s12193-024-00447-8 | C75: The effects of haptic, visual and olfactory augmentations on food consumed while wearing an extended reality headset | D75: 2024 | E75: Springer | F75: https://link.springer.com/article/10.1007/s12193-024-00447-8 | G75: Varjo XR-3 extended reality headset - QR-code tracking cube - Electromagnetic actuators - Arduino control system - Olfactory necklace display - Air compressor + odor bottles | H75: Included | I75: Paper employs haptic, visual, and olfactory feedback delivered via an extended reality headset to alter how people perceive food. this is linked to the Super Brain concept, as it utilizes sensory-based technology to modify human sensory perception. | J75: Plant-based foods can be healthier and more sustainable, but they may not provide the same pleasant eating experience people expect from conventional foods. | K75: A multisensory XR system combining visual + haptic + olfactory augmentation. | L75: Tactile & Sensory Substitution Systems (TSSS) | M75: Tactile-Actuation, Human-Factors-Usability, Wearable-Embedded | N75: Original assignment for Mostafa (Row 75) | O75: Primary SLR Target | P75: REF-069
A76: Mostafa | B76: 10.1007/s12193-023-00427-4 | C76: Review of substitutive assistive tools and technologies for people with visual impairments: recent advancements and prospects | D76: 2023 | E76: Springer | F76: https://link.springer.com/article/10.1007/s12193-023-00427-4 | G76: Electronic Travel Aids (ETAs) - Sensory substitution devices - Computer vision systems - Wearable haptic devices - Audio-based navigation systems - AI and machine learning | H76: Included | I76: The paper explores assistive and sensory-based technologies designed for the blind and visually impaired including visual, auditory, and tactile systems. This ties into the Super Brain concept, as it involves technologies that compensate for the sense of sight or support it by utilizing other sensory inputs. | J76: There are various technologies designed primarily to assist visually impaired individuals with their work, but they suffer from issues regarding ease of use and ease of learning. | K76: User-centered + multimodal assistive technology, with visually impaired users involved throughout design and testing. | L76: Tactile & Sensory Substitution Systems (TSSS) | M76: Tactile-Actuation, AI-Object-Detection, Corridor-Navigation, Human-Factors-Usability, Wearable-Embedded | N76: Original assignment for Mostafa (Row 76) | O76: Primary SLR Target | P76: REF-070
...

Sheet Mohsen
B1: Paper's DOI | C1: Title | D1: Publication Year | E1: Publisher | F1: paper URL | G1: Technology | H1: Included or Excluded | I1: Reason for inclusivity | J1: Problem | K1: Solution | L1: Main Tag | M1: Another Tags | N1: Custom Numbering M-## | O1: Additionals Notes
A2: Mohsen | B2: x | H2: excluded | I2: unknown
B3: x | H3: excluded | I3: unknown
B4: x | H4: excluded | I4: unknown
B5: x | H5: excluded | I5: unknown
B6: x | H6: excluded | I6: unknown
B7: x | H7: excluded | I7: unknown
B8: 10.1109/ACCESS.2025.3548552 | C8: Sensory Substitution Device for Time Presentation: Spatial–Temporal Vibrotactile Encoding for Presenting Time on the Human Wrist | D8: `10-Mar-202 | E8: IEEE | F8: https://doi.org/10.1109/ACCESS.2025.3548552?utm_source=chatgpt.com | G8: Vibrotactile feedback, Arduino Mega (ATmega2560), vibration motors | H8: included | I8: Relevant to wearable haptic feedback and tactile information encoding. | J8: Communicating information through vibration patterns that users can understand accurately. | K8: A wrist-worn device that represents time using spatial and temporal vibration patterns. | L8: #wearable-tech | M8: #wearable-tech, #assistive-technology, #embedded-systems, #microcontroller, #accessibility, #visual-impairment | N8: M-01 | O8: The paper focuses on presenting time through vibration, not AI-based environmental perception or navigation.
B9: doi:10.1016/j.tics.2003.10.013 | C9: Sensory substitution and the human–machine interface | D9: 37967 | H9: excluded | I9: date
B10: x | C10: Obstacle Detection, Depth Estimation And Warning System For Visually Impaired People | H10: excluded | I10: date
B11: https://doi.org/10.1007/s13042-023-01887-6 | C11: Structured deep learning based object‐specific distance estimation from a monocular image | D11: 45088 | E11: Springer | F11: https://link.springer.com/article/10.1007/s13042-023-01887-6 | H11: included | N11: M-02 | O11: CAN'T Reach the pdf yet
B12: 10.1109/TOH.2021.3077619 | C12: Survey of Pseudo-Haptics: Haptic Feedback Design and Application Proposals | D12: OCTOBER-DECEMBER 2021 | E12: IEEE | H12: excluded | I12: survey
B13: 10.1177/10711813251360706 | C13: Navigation Assistance Via Haptic Technology for Blind or Low-Vision Users: A Scoping Review | D13: 45866 | E13: SAGE | F13: https://journals.sagepub.com/doi/10.1177/10711813251360706 | G13: Review paper (Has No one technology) | H13: included | I13: Directly focuses on haptic and tactile technologies used to help blind or low-vision users navigate and receive directional guidance or obstacle warnings. | J13: Same Our Problem | K13: Review and evaluate haptic navigation approaches that communicate directions and obstacles through vibration, skin-stretch, or force feedback, sometimes combined with audio feedback. | L13: #assistive-technology | M13: #wearable-tech, #visual-impairment, #accessibility, #embedded-systems | N13: M-03 | O13: Exactly like what we want to do (Very Important) --- this paper mention also some papers talks about sound solutions not only haptic
A14: Mohsen | B14: https://papers.ssrn.com/sol3/papers.cfm?abstract_id=4989285 10.1109/TASE.2020.2971713 | C14: Toward Image-to-Tactile Cross-Modal Perception for Visually Impaired People | D14: 44287 | E14: IEEE | F14: https://ieeexplore.ieee.org/abstract/document/9018269 | H14: included | N14: M-04 | O14: not peer reviewed (Need ask if this work or no)
B15: https://doi.org/10.1007/s12193-025-00452-5 | C15: Vis-Assist: computer vision and haptic feedback-based wearable assistive device for visually impaired | D15: 45800 | E15: Springer | F15: https://link.springer.com/article/10.1007/s12193-025-00452-5 | H15: included | N15: M-05 | O15: CAN'T Reach the pdf yet
B16: doi:10.1016/j.concog.2009.10.006 | C16: Visual experiences in the blind induced by an auditory sensory substitution device | D16: 40148 | E16: sciencedirect | F16: https://www.sciencedirect.com/science/article/abs/pii/S1053810009001718?via%3Dihub | H16: excluded | I16: date
B17: x | H17: excluded
B26: =IF(C26="","","PID-"&TEXT(ROW()-2,"0000"))
B27: =IF(C27="","","PID-"&TEXT(ROW()-2,"0000"))
B28: =IF(C28="","","PID-"&TEXT(ROW()-2,"0000"))
B30: 0 | C30: Need to look for these
B31: 1 | C31: https://hal.science/hal-01993932v1/document
B32: =IF(C32="","","PID-"&TEXT(ROW()-2,"0000"))
B33: =IF(C33="","","PID-"&TEXT(ROW()-2,"0000"))
B34: =IF(C34="","","PID-"&TEXT(ROW()-2,"0000"))
B35: =IF(C35="","","PID-"&TEXT(ROW()-2,"0000"))
B36: =IF(C36="","","PID-"&TEXT(ROW()-2,"0000"))
B37: =IF(C37="","","PID-"&TEXT(ROW()-2,"0000"))
B38: =IF(C38="","","PID-"&TEXT(ROW()-2,"0000"))
B39: =IF(C39="","","PID-"&TEXT(ROW()-2,"0000"))
B40: =IF(C40="","","PID-"&TEXT(ROW()-2,"0000"))
B41: =IF(C41="","","PID-"&TEXT(ROW()-2,"0000"))
B42: =IF(C42="","","PID-"&TEXT(ROW()-2,"0000"))
B43: =IF(C43="","","PID-"&TEXT(ROW()-2,"0000"))
... B84: =IF(C84="","","PID-"&TEXT(ROW()-2,"0000"))

Sheet Ahmed
B1: Paper's DOI | C1: Title | D1: Publication Year | E1: Publisher | F1: paper URL | G1: Technology | H1: Included or Excluded | I1: Reason for inclusivity | J1: Problem | K1: Solution | L1: Main Tags | M1: Another Tags
A2: David | B2: 10.1016/j.bcp.2025.116272 | C2: A quantitative assessment of EOG eye tracking during free viewing in sighted and in congenitally blind | D2: 2025 | E2: Elsevier | F2: https://www.sciencedirect.com/science/article/pii/S0006899325003555?via%3Dihub | G2: Electrooculography (EOG) Video-Based Eye Tracking SMI Eye-Tracking Glasses Smarting Mobile EEG g.HIamp Amplifier BioSemi EEG vEOG / hEOG Blink Detection Saccade Detection The vOICe | H2: included | J2: Limited exploration of EOG in naturalistic/free-viewing conditions Video-based tracking can fail in blind individuals due to pupil abnormalities or eyelid control Need to detect eye movements without visual fixation | K2: EOG-based detection of blinks and saccades Comparison with video-based eye tracking Testing under light, darkness, eyes-closed, and congenital blindness Demonstrated that EOG can detect eye movements in blind participants
B3: 10.1016/j.neuroimage.2025.121652 | C3: Long-term visual-to-tactile stimulation induces functional reorganization of thalamic pathways to achieve visual perception | D3: 2025 | E3: Elsevier | F3: https://www.sciencedirect.com/science/article/pii/S105381192500655X?via%3Dihub | G3: Sensory Substitution Device (SSD) Visual-to-Tactile Conversion Tactile Stimulation Resting-State fMRI Functional Connectivity Analysis Thalamic/Occipital Brain Imaging | H3: included | J3: Limited understanding of how long-term tactile sensory substitution produces visual perception. Unclear how the brain reorganizes its pathways during prolonged SSD use. | K3: Long-term visual-to-tactile stimulation/training. Investigation of changes in thalamic–occipital connectivity to understand the neural mechanism.
B4: 10.1016/j.neuroimage.2021.118029 | C4: Topographic maps and neural tuning for sensory substitution dimensions learned in adulthood in a congenital blind subject | D4: 2021 | E4: Elsevier | F4: https://www.sciencedirect.com/science/article/pii/S1053811921003062?via%3Dihub | G4: Auditory Sensory Substitution Device 2D Auditory Soundscape Pitch Encoding Temporal Encoding Population Receptive Field Mapping fMRI | H4: included | J4: How the adult brain represents newly learned sensory dimensions in a person who is congenitally blind. | K4: Convert spatial information into auditory dimensions. Train the participant to interpret the auditory representation. Analyze the resulting neural maps and tuning.
B5: 10.1016/j.neuroimage.2024.120621 | C5: Visual Mental Imagery and Neural Dynamics of Sensory Substitution in the Blindfolded Subjects | D5: 2024 | E5: Elsevier | F5: https://www.sciencedirect.com/science/article/pii/S1053811924001162?via%3Dihub | G5: Auditory Sensory Substitution Visual-to-Auditory Encoding Soundscape Stimuli Functional MRI Dynamic Causal Modeling (DCM) Visual Mental Imagery | H5: included | J5: How sensory-substitution information is processed by the brain. Whether auditory sensory substitution can engage visual mental imagery. | K5: Train subjects to interpret auditory representations of visual shapes. Use neuroimaging and DCM to analyze the resulting brain-network dynamics.
B6: 10.1177/0145482X19842491 | C6: A Haptic Navigation Aid for Individuals with Visual Impairments: Indoor and Outdoor Feasibility Evaluations of the LaserNavigator | D6: 2019 | E6: SAGE Publications | F6: https://journals.sagepub.com/doi/10.1177/0145482X19842491 | G6: Laser Rangefinder Haptic Feedback Vibrating Actuator Handheld Device Virtual White Cane Variable Virtual Cane Length | H6: included | J6: Conventional white canes have a limited detection range. | K6: Use a laser rangefinder to detect objects beyond normal cane range. Convert measured distance into haptic feedback.
B7: 10.5220/0006617505550562 | C7: Wearable RGB Camera-based Navigation System for the Visually Impaired | D7: 2018 | E7: SciTePress | F7: https://www.scitepress.org/PublishedPapers/2018/66175/ | H7: Excluded | I7: Published by SciTePress
B8: 10.1609/aaai.v37i2.25233 | C8: BEVDepth: Acquisition of Reliable Depth for Multi-View 3D Object Detection | D8: 2023 | E8: AAAI | F8: https://ojs.aaai.org/index.php/AAAI/article/view/25233 | H8: Excluded | I8: Because it falls in a different feild of study and is published by AAAI
B9: 10.1109/EMBC.2013.6611022 | C9: Electrotactile vision substitution for 3D trajectory following | D9: 2013 | E9: IEEE | F9: https://ieeexplore.ieee.org/document/6611022 | H9: Excluded | I9: Published in 2013 and The linked IEEE document does not appear to correspond to the assistive-vision/navigation research needed for your review
B10: 10.1109/EIT51626.2021.9491913 | C10: Visually Impaired Indoor Navigation using YOLO Based Object Recognition, Monocular Depth Estimation and Binaural Sounds | D10: 2021 | E10: IEEE | F10: https://ieeexplore.ieee.org/document/9491913 | G10: Monocular RGB Camera Deep Learning ResNet-50 Backbone Encoder–Decoder Network YOLOv8 Object Detection Monocular Depth Estimation Object Distance Estimation D-Far250 Dataset KITTI Dataset Binaural/Spatial Audio HRTF | H10: included | J10: Difficulty detecting objects and understanding their distance and spatial position during indoor navigation. | K10: YOLO detects objects. Monocular depth estimation estimates object distance. Spatial information is converted into binaural audio. Audio provides directional and distance information to the user.
B11: 10.1109/TITS.2022.3161141 | C11: Trans4Trans: Efficient Transformer for Transparent Object and Semantic Scene Segmentation in Real-World Navigation Assistance | D11: 2021 | E11: arXiv | F11: https://ieeexplore.ieee.org/document/9743965 | G11: RGB-D Camera Portable GPU Trans4Trans Transformer Transformer Parsing Module (TPM) Semantic Segmentation Transparent Object Segmentation Depth Information Bone-Conduction Earphone | H11: included | J11: Transparent objects such as glass doors and glass walls can be incorrectly interpreted as free/walkable space. | K11: Detect transparent objects separately. Combine transparent-object segmentation with semantic segmentation and depth information. Provide navigation feedback to the visually impaired user.
B12: 10.1109/TOH.2021.3138590 | C12: In-Device Feedback in Immersive Head-Mounted Displays for Distance Perception During Teleoperation of Unmanned Ground Vehicles | D12: 2022 | E12: arXiv | F12: https://ieeexplore.ieee.org/document/9664257 | H12: Excluded | I12: Different feild of study (The actual application is remote control of unmanned ground vehicles0
B13: 10.48550/arXiv.2201.04453 | C13: Obstacle Avoidance for Blind People Using a 3D Camera and a Haptic Feedback Sleeve | D13: 2022 | E13: arXiv / CoRR | F13: https://arxiv.org/abs/2201.04453 | G13: Intel RealSense D415 3D Camera 3D Point Cloud Depth Mapping AAEON Up Board 5×5 Haptic Feedback Sleeve Vibration Motor Array Spatial Depth-to-Haptic Mapping 3D-Printed Glasses | H13: included | J13: Limited obstacle detection range using conventional aids. Difficulty providing multidimensional information about obstacles. Some existing approaches depend on lighting conditions. | K13: Capture 3D depth information using the RealSense camera. Convert the depth map into a 5×5 spatial representation. Map each region to a corresponding vibration motor. Use vibration intensity to communicate obstacle distance.
A14: salma | B14: 10.1080/23311916.2025.2560974 | C14: An assistive haptic-based obstacle avoidance system for individuals with profound visual impairment | D14: 2025 | E14: Taylor & Francis | F14: https://www.tandfonline.com/doi/full/10.1080/23311916.2025.2560974 | G14: X | H14: Excluded | I14: because paper published by taylor that not included in our scope | J14: X | K14: X
B15: https://doi.org/10.1002/aisy.70450Digital Object Identifier (DOI) | C15: Enhanced Monocular Depth Estimation Using ResNet Backbone and Multiscale Feature Decoding for Precise Object Distance Measurement | D15: 2026 | E15: Wiley | F15: https://advanced.onlinelibrary.wiley.com/doi/10.1002/aisy.70450 | H15: included
C16: Duplicated | H16: Execlauded
C17: Sight Guide: A Wearable Assistive Perception and Navigation System for the Vision Assistance Race in the Cybathlon 2024 | D17: 2025 | E17: Arixiv | H17: Excluded
B18: 10.1109/ICRA40945.2020.9196782 | C18: A Visual Positioning System for Indoor Blind Navigation | D18: 2020 | E18: IEEE | F18: https://www.researchgate.net/publication/339725908_A_Visual_Positioning_System_for_Indoor_Blind_Navigation | H18: included
B19: 10.1109/ACCESS.2023.3244073 | C19: A Survey on Outdoor Navigation Applications for People With Visual Impairments | D19: 2023 | E19: IEEE | F19: https://ieeexplore.ieee.org/document/10041898 | H19: included
B20: https://doi.org/10.1016/j.eswa.2023.121065 | C20: A data fusion framework based on heterogeneous information network embedding for trigger-action programming in IoT | D20: 2023 | E20: Elsevier | F20: https://www.sciencedirect.com/science/article/abs/pii/S0957417423015671?via%3Dihub | H20: included
B21: https://doi.org/10.48550/arXiv.2511.10026 | C21: Grating haptic perception through touchscreen: Sighted vs. Visually Impaired | D21: 2026 | E21: arXiv | F21: https://arxiv.org/abs/2511.10026v3 | G21: X | H21: Excluded | I21: because paper published by arix that not included in our scope | J21: X | K21: X
B22: https://doi.org/10.1007/s42486-023-00136-7 | C22: A smart obstacle avoiding technology based on depth camera for blind and visually impaired people (Commentry) | D22: 2023 | E22: Springer | F22: https://link.springer.com/article/10.1007/s42486-023-00136-7 | H22: Excluded
B23: 10.1177/20552076251408522 | C23: Sensory-driven micro-interventions for improved health and wellbeing | D23: 2025 | E23: Sage | F23: https://journals.sagepub.com/doi/10.1177/20552076251408522 | H23: included
H25: Excluded
A26: Taha | B26: 10.3233/APC210058 | C26: A Robotic Assisted System Using Deep Learning for Navigation and Reading IoT Based Home Automation for Visually Impaired | D26: 2021 | E26: IOS Press | F26: https://ebooks.iospress.nl/doi/10.3233/APC210058 | G26: X | H26: Excluded | I26: because paper published by IOS press that not included in our scope | J26: X | K26: X
B27: 10.1196/annals.1305.006 | C27: Tactile Sensory Substitution Studies | D27: 2004 | E27: Wiley | F27: https://nyaspubs.onlinelibrary.wiley.com/doi/epdf/10.1196/annals.1305.006 | G27: camera - Sensory Substitution - Tongue Electrotactile Interface - Vibrotactile Stimulation | H27: included | I27: The paper is included because it helps blind users by explaining sensory substitution by info from camera converted into tactile information that brain can learn to understand | J27: problem is to how to provide a visiual info to blind peoples by using tactile stimulation the chalenge is to create an effective brain -machine interface(BMI) | K27: the paper uses: 1-sensory substitution system : converts visual info from a camera into tactile (electrotactile stimulation) 2-stimulation is delivered through tactile arrays 3-electrotactile interface on the tongue 4-allow brain to learn and interpert the info
B28: 10.1016/j.asej.2023.102387 | C28: An effective obstacle detection system using deep learning advantages to aid blind and visually impaired navigation | D28: 2024 | E28: Elsevier | F28: https://www.sciencedirect.com/science/article/pii/S2090447923002769?via%3Dihub | G28: Deep Learning Modified YOLOv5 Computer Vision Obstacle/Object Detection Indoor & Outdoor Environment Model optimization for deployment on embedded devices | H28: included | I28: Paper focus on obstacle detection for blind using YOLOv5 model it cover indoor andoutdoor objects and uses optimization method to make model lightweight | J28: Blind and visually impaired people have difficulty detecting obstacles and navigating safely in their surroundings. | K28: The paper proposes a modified YOLOv5-based obstacle detection system to detect objects/obstacles and provide information that can assist blind and visually impaired users during navigation
B29: 10.1109/JAS.2021.1004084 | C29: An RGB-D Camera Based Visual Positioning System for Assistive Navigation by a Robotic Navigation Aid | D29: 2021 | E29: IEEE | F29: https://www.ieee-jas.net/article/doi/10.1109/JAS.2021.1004084?pageType=en | G29: RGB-D Camera IMU Visual-Inertial Odometry (VIO) 6-DOF Pose Estimation Particle Filter Localization Indoor CAD/Floor Plans Path Planning & Obstacle Avoidance Real-time processing | H29: Included | I29: Because it focuses on assistiv navigation for impaired users and combine computer vision with RGB and real time navigation | J29: blind people need reliable navigation assistance in large indoor environments Existing mobility tools such as white canes and guide dogs do not provide electronic localization/navigation information | K29: The paper develops a real-time visual positioning system for a robotic navigation aid. It combines an RGB-D camera + IMU to estimate the device's 6-DOF pose, then uses a particle filter and indoor CAD floor-plan information to reduce localization error and support wayfinding
C30: duplicated | H30: Excluded
B31: X | C31: X | D31: X | E31: Taylor & Francis | F31: https://www.tandfonline.com/doi/epdf/10.1080/23311916.2025.2560974?needAccess=true | G31: X | H31: Excluded | I31: because paper published by taylor press that not included in our scope | J31: X | K31: X
B32: 10.1177/20552076251408522 | C32: Sensory-driven micro-interventions for improved health and wellbeing | D32: 2025 | E32: Sage | F32: https://journals.sagepub.com/home/dhj | G32: AI / Machine Learning IoT Wearable sensors Sensory devices & interfaces Real-time data collection and processing Sensory substitution Vibrotactile / haptic feedback Smartphones and connected devices Embedded sensors | H32: included | I32: included because paper support sensory substituation and hapitic feedback concept of super Brain it discusses technologies that convert environmental/visual information into tactile feedback for visually impaired users | J32: sensory technologies work separately there no simple system for continuously monitoring sensory changes and providing personalized help when needed | K32: The paper proposes using AI IoT wearable sensors and sensory devices to monitor sensory changes and provide personalized sensory training
B33: 10.1007/s42486-023-00136-7 | C33: A smart obstacle avoiding technology based on depth camera for blind and visually impaired people | D33: 2023 | E33: Springer Nature | F33: https://link.springer.com/article/10.1007/s42486-023-00136-7? | G33: Depth/RGB-D Camera — Intel RealSense D435i 3D Point Cloud L-PointPillars Deep Learning / Neural Network Depthwise Separable Convolution Attention Mechanism NVIDIA Jetson Xavier NX PyTorch + Python Text-to-Speech (TTS) Audio Feedback | H33: included | I33: Included because it uses a depth camera and AI-based obstacle detection to help blind and visually impaired people navigate safely outdoors | J33: impaired people difficult detecting and avoiding obstacles when traveling outdoors. Existing assistive devices have limited detection range and limited computing power | K33: The paper proposes a wearable system that uses a depth camera and L-PointPillars to detect obstacles in real time and gives audio information about the obstacle and its distance
