Workbook
Name B111D111: Fathy!$C$111:$C$111
Name F100H100: Fathy!$G$100:$G$100
Name F101H101: Fathy!$G$101:$G$101
Name F102H102: Fathy!$G$102:$G$102
Name F98H98: Fathy!$G$98:$G$98
Name F99H99: Fathy!$G$99:$G$99
Name H110J110: Fathy!$I$110:$I$110
Name H111J111: Fathy!$I$111:$I$111
Name L100B101: Fathy!$A$98:$A$109
Name L101B102: Fathy!$A$98:$A$109
Name L102B103: Fathy!$A$98:$A$109
Name L104B105: Fathy!$A$98:$A$109
Name L99B100: Fathy!$A$98:$A$109

Sheet Main 
B1: Paper's DOI | C1: Title | D1: Publication Year | E1: Publisher | F1: paper URL | G1: Technology | H1: Included or Excluded | I1: Reason for inclusivity | J1: Problem | K1: Solution | L1: Main Tags | M1: Another Tags | N1: Column1 | O1: Column2 | P1: Numbering for ref
A2: David | B2: 10.1016/j.bcp.2025.116272 | C2: A quantitative assessment of EOG eye tracking during free viewing in sighted and in congenitally blind | D2: 2025 | E2: Elsevier | F2: https://www.sciencedirect.com/science/article/pii/S0006899325003555?via%3Dihub | G2: Electrooculography (EOG) Video-Based Eye Tracking SMI Eye-Tracking Glasses Smarting Mobile EEG g.HIamp Amplifier BioSemi EEG vEOG / hEOG Blink Detection Saccade Detection The vOICe | H2: included | J2: Limited exploration of EOG in naturalistic/free-viewing conditions Video-based tracking can fail in blind individuals due to pupil abnormalities or eyelid control Need to detect eye movements without visual fixation | K2: EOG-based detection of blinks and saccades Comparison with video-based eye tracking Testing under light, darkness, eyes-closed, and congenital blindness Demonstrated that EOG can detect eye movements in blind participants | L2: #AI | M2: #assistive-technology, #edge-ai, #embedded-systems, #wearable-tech, #computer-vision, #internet-of-things, #IoMT, #visual-impairment, #real-time-inference, #microcontroller, #ESP32, #RaspberryPi, #STM32, #accessibility, #haptic-feedback, #sensory-substitution, #obstacle-detection, #AI #computer-vision | P2: 1
B3: 10.1016/j.neuroimage.2025.121652 | C3: Long-term visual-to-tactile stimulation induces functional reorganization of thalamic pathways to achieve visual perception | D3: 2025 | E3: Elsevier | F3: https://www.sciencedirect.com/science/article/pii/S105381192500655X?via%3Dihub | G3: Sensory Substitution Device (SSD) Visual-to-Tactile Conversion Tactile Stimulation Resting-State fMRI Functional Connectivity Analysis Thalamic/Occipital Brain Imaging | H3: included | J3: Limited understanding of how long-term tactile sensory substitution produces visual perception. Unclear how the brain reorganizes its pathways during prolonged SSD use. | K3: Long-term visual-to-tactile stimulation/training. Investigation of changes in thalamic–occipital connectivity to understand the neural mechanism. | P3: 2
B4: 10.1016/j.neuroimage.2021.118029 | C4: Topographic maps and neural tuning for sensory substitution dimensions learned in adulthood in a congenital blind subject | D4: 2021 | E4: Elsevier | F4: https://www.sciencedirect.com/science/article/pii/S1053811921003062?via%3Dihub | G4: Auditory Sensory Substitution Device 2D Auditory Soundscape Pitch Encoding Temporal Encoding Population Receptive Field Mapping fMRI | H4: included | J4: How the adult brain represents newly learned sensory dimensions in a person who is congenitally blind. | K4: Convert spatial information into auditory dimensions. Train the participant to interpret the auditory representation. Analyze the resulting neural maps and tuning. | P4: 3
B5: 10.1016/j.neuroimage.2024.120621 | C5: Visual Mental Imagery and Neural Dynamics of Sensory Substitution in the Blindfolded Subjects | D5: 2024 | E5: Elsevier | F5: https://www.sciencedirect.com/science/article/pii/S1053811924001162?via%3Dihub | G5: Auditory Sensory Substitution Visual-to-Auditory Encoding Soundscape Stimuli Functional MRI Dynamic Causal Modeling (DCM) Visual Mental Imagery | H5: included | J5: How sensory-substitution information is processed by the brain. Whether auditory sensory substitution can engage visual mental imagery. | K5: Train subjects to interpret auditory representations of visual shapes. Use neuroimaging and DCM to analyze the resulting brain-network dynamics. | P5: 4
B6: 10.1177/0145482X19842491 | C6: A Haptic Navigation Aid for Individuals with Visual Impairments: Indoor and Outdoor Feasibility Evaluations of the LaserNavigator | D6: 2019 | E6: SAGE Publications | F6: https://journals.sagepub.com/doi/10.1177/0145482X19842491 | G6: Laser Rangefinder Haptic Feedback Vibrating Actuator Handheld Device Virtual White Cane Variable Virtual Cane Length | H6: included | J6: Conventional white canes have a limited detection range. | K6: Use a laser rangefinder to detect objects beyond normal cane range. Convert measured distance into haptic feedback. | P6: 5
B7: 10.5220/0006617505550562 | C7: Wearable RGB Camera-based Navigation System for the Visually Impaired | D7: 2018 | E7: SciTePress | F7: https://www.scitepress.org/PublishedPapers/2018/66175/ | H7: Excluded | I7: Published by SciTePress | P7: 6
B8: 10.1609/aaai.v37i2.25233 | C8: BEVDepth: Acquisition of Reliable Depth for Multi-View 3D Object Detection | D8: 2023 | E8: AAAI | F8: https://ojs.aaai.org/index.php/AAAI/article/view/25233 | H8: Excluded | I8: Because it falls in a different feild of study and is published by AAAI | P8: 7
B9: 10.1109/EMBC.2013.6611022 | C9: Electrotactile vision substitution for 3D trajectory following | D9: 2013 | E9: IEEE | F9: https://ieeexplore.ieee.org/document/6611022 | H9: Excluded | I9: Published in 2013 and The linked IEEE document does not appear to correspond to the assistive-vision/navigation research needed for your review | P9: 8
B10: 10.1109/EIT51626.2021.9491913 | C10: Visually Impaired Indoor Navigation using YOLO Based Object Recognition, Monocular Depth Estimation and Binaural Sounds | D10: 2021 | E10: IEEE | F10: https://ieeexplore.ieee.org/document/9491913 | G10: Monocular RGB Camera Deep Learning ResNet-50 Backbone Encoder–Decoder Network YOLOv8 Object Detection Monocular Depth Estimation Object Distance Estimation D-Far250 Dataset KITTI Dataset Binaural/Spatial Audio HRTF | H10: included | J10: Difficulty detecting objects and understanding their distance and spatial position during indoor navigation. | K10: YOLO detects objects. Monocular depth estimation estimates object distance. Spatial information is converted into binaural audio. Audio provides directional and distance information to the user. | P10: 9
B11: 10.1109/TITS.2022.3161141 | C11: Trans4Trans: Efficient Transformer for Transparent Object and Semantic Scene Segmentation in Real-World Navigation Assistance | D11: 2021 | E11: arXiv | F11: https://ieeexplore.ieee.org/document/9743965 | G11: RGB-D Camera Portable GPU Trans4Trans Transformer Transformer Parsing Module (TPM) Semantic Segmentation Transparent Object Segmentation Depth Information Bone-Conduction Earphone | H11: included | J11: Transparent objects such as glass doors and glass walls can be incorrectly interpreted as free/walkable space. | K11: Detect transparent objects separately. Combine transparent-object segmentation with semantic segmentation and depth information. Provide navigation feedback to the visually impaired user. | P11: 10
B12: 10.1109/TOH.2021.3138590 | C12: In-Device Feedback in Immersive Head-Mounted Displays for Distance Perception During Teleoperation of Unmanned Ground Vehicles | D12: 2022 | E12: arXiv | F12: https://ieeexplore.ieee.org/document/9664257 | H12: Excluded | I12: Different feild of study (The actual application is remote control of unmanned ground vehicles0 | P12: 11
B13: 10.48550/arXiv.2201.04453 | C13: Obstacle Avoidance for Blind People Using a 3D Camera and a Haptic Feedback Sleeve | D13: 2022 | E13: arXiv / CoRR | F13: https://arxiv.org/abs/2201.04453 | G13: Intel RealSense D415 3D Camera 3D Point Cloud Depth Mapping AAEON Up Board 5×5 Haptic Feedback Sleeve Vibration Motor Array Spatial Depth-to-Haptic Mapping 3D-Printed Glasses | H13: included | J13: Limited obstacle detection range using conventional aids. Difficulty providing multidimensional information about obstacles. Some existing approaches depend on lighting conditions. | K13: Capture 3D depth information using the RealSense camera. Convert the depth map into a 5×5 spatial representation. Map each region to a corresponding vibration motor. Use vibration intensity to communicate obstacle distance. | P13: 12
A14: salma | B14: 10.1080/23311916.2025.2560974 | C14: An assistive haptic-based obstacle avoidance system for individuals with profound visual impairment | D14: 2025 | E14: Taylor & Francis | F14: https://www.tandfonline.com/doi/full/10.1080/23311916.2025.2560974 | G14: X | H14: Excluded | I14: because paper published by taylor that not included in our scope | J14: X | K14: X
B15: https://doi.org/10.1002/aisy.70450Digital Object Identifier (DOI) | C15: Enhanced Monocular Depth Estimation Using ResNet Backbone and Multiscale Feature Decoding for Precise Object Distance Measurement | D15: 2026 | E15: Wiley | F15: https://advanced.onlinelibrary.wiley.com/doi/10.1002/aisy.70450 | G15: ResNet-18, YOLOv8, Deep Learning, CNN, Multiscale Feature Decoding, 16-bit Depth Maps | H15: included | J15: Inaccurate long-range distance estimation from a single camera image; existing methods have limited range and high hardware costs. | K15: ResNet-18 encoder-decoder with multiscale supervision, integrated with YOLOv8 for object detection and distance estimation up to 250 m.
B16: https://doi.org/10.1145/3663547.374633 | C16: Tactile Data Comics: Combining Step-by-step Presentation of Tactile Graphics with Verbal Narration for the Blind and Visually Impaired | E16: ACM | F16: https://dl.acm.org/doi/10.1145/3663547.3746338 | H16: Excluded
C17: Sight Guide: A Wearable Assistive Perception and Navigation System for the Vision Assistance Race in the Cybathlon 2024 | D17: 2025 | E17: Arixiv | H17: Excluded
B18: 10.1109/ICRA40945.2020.9196782 | C18: A Visual Positioning System for Indoor Blind Navigation | D18: 2020 | E18: IEEE | F18: https://www.researchgate.net/publication/339725908_A_Visual_Positioning_System_for_Indoor_Blind_Navigation | G18: RGB-D Camera, IMU, Visual-Inertial Odometry (DVIO), Particle Filter Localization (PFL), ROS, SLAM | H18: included | J18: Existing indoor navigation systems struggle in textureless environments and often require powerful external computers. | K18: Combines depth-enhanced visual-inertial odometry with particle-filter localization for indoor positioning, path planning, and obstacle avoidance.
B19: 10.1109/ACCESS.2023.3244073 | C19: A Survey on Outdoor Navigation Applications for People With Visual Impairments | D19: 2023 | E19: IEEE | F19: https://ieeexplore.ieee.org/document/10041898 | G19: Deep Learning Computer Vision GPS Localization Sensory Substitution Devices Geographic Information Systems | H19: included | J19: Existing navigation apps lack critical accessibility and hazard information, causing frequent injuries and low independence for visually impaired pedestrians. | K19: A four-phase assistive navigation framework that plans and guides routes based on safety, controlled intersections, and obstacle avoidance instead of distance.
B20: https://doi.org/10.1016/j.eswa.2023.121065 | C20: A data fusion framework based on heterogeneous information network embedding for trigger-action programming in IoT | D20: 2023 | E20: Elsevier | F20: https://www.sciencedirect.com/science/article/abs/pii/S0957417423015671?via%3Dihub | G20: Heterogeneous Information Networks Graph Representation Learning Metagraph-Guided Random Walk Natural Language Processing Multi-Label Classification | H20: included | J20: Manual creation of IoT trigger-action rules is impractical due to exponential device combinations, and existing methods fail to bridge semantics between user descriptions and device interactions. | K20: A data fusion framework named TAPFuser that maps natural language demands to IoT recipes using heterogeneous network embedding and metagraph-guided random walks.
B21: https://doi.org/10.48550/arXiv.2511.10026 | C21: Grating haptic perception through touchscreen: Sighted vs. Visually Impaired | D21: 2026 | E21: arXiv | F21: https://arxiv.org/abs/2511.10026v3 | G21: X | H21: Excluded | I21: because paper published by arix that not included in our scope | J21: X | K21: X
B22: https://doi.org/10.1007/s42486-023-00136-7 | C22: A smart obstacle avoiding technology based on depth camera for blind and visually impaired people (Regular Paper) | D22: 2023 | E22: Springer | F22: https://link.springer.com/article/10.1007/s42486-023-00136-7 | G22: Point Cloud Processing Depthwise Separable Convolution 3D Object Detection Attention Mechanism Edge Computing | H22: included | J22: Existing 3D obstacle detection models are too computationally heavy and power-intensive for real-time execution on low-cost wearable edge devices for visually impaired pedestrians. | K22: A lightweight 3D obstacle detection network called L-PointPillars deployed on a wearable edge device to provide real-time audio warnings with significantly reduced parameters.
B23: 10.1177/20552076251408522 | C23: Sensory-driven micro-interventions for improved health and wellbeing(Commentary) | D23: 2025 | E23: Sage | F23: https://journals.sagepub.com/doi/10.1177/20552076251408522 | G23: Wearable Sensors Internet of Things Machine Learning Sensory Substitution Systems Digital Olfactory Interfaces | H23: included | J23: Age- and disease-related sensory decline often goes undetected until late stages, lacking proactive and personalized interventions in daily life. | K23: A digital healthcare paradigm of sensory-driven micro-interventions that tracks sensory changes through daily technology interactions and delivers timely, personalized sensory stimulation.
B24: https://doi.org/10.1038/s41928-023-01074-z | C24: A skin-integrated multimodal haptic interface for immersive tactile feedback | D24: 2023 | E24: Nature | F24: https://www.nature.com/articles/s41928-023-01074-z | G24: Multimodal Haptic Feedback, Mechanical Actuators, Electrotactile Stimulation, Thermoelectric Actuators, BLE, VR | H24: included | J24: Wearable haptic devices provide limited feedback, mainly simple vibration and single tactile sensations. | K24: Skin-integrated multimodal interface combining thermal, mechanical and electrotactile feedback to reproduce diverse tactile sensations.
B25: https://doi.org/10.1145/3517428.3544797 | C25: Animations at Your Fingertips: Using a Refreshable Tactile Display to Convey Motion Graphics for People who are Blind or have Low Vision | D25: 2022 | E25: ACM | F25: https://dl.acm.org/doi/10.1145/3517428.354479 | H25: Excluded
A26: Taha | B26: 10.3233/APC210058 | C26: A Robotic Assisted System Using Deep Learning for Navigation and Reading IoT Based Home Automation for Visually Impaired | D26: 2021 | E26: IOS Press | F26: https://ebooks.iospress.nl/doi/10.3233/APC210058 | G26: X | H26: Excluded | I26: because paper published by IOS press that not included in our scope | J26: X | K26: X | P26: 25
B27: 10.1196/annals.1305.006 | C27: Tactile Sensory Substitution Studies | D27: 2004 | E27: Wiley | F27: https://nyaspubs.onlinelibrary.wiley.com/doi/epdf/10.1196/annals.1305.006 | G27: camera - Sensory Substitution - Tongue Electrotactile Interface - Vibrotactile Stimulation | H27: included | I27: The paper is included because it helps blind users by explaining sensory substitution by info from camera converted into tactile information that brain can learn to understand | J27: problem is to how to provide a visiual info to blind peoples by using tactile stimulation the chalenge is to create an effective brain -machine interface(BMI) | K27: the paper uses: 1-sensory substitution system : converts visual info from a camera into tactile (electrotactile stimulation) 2-stimulation is delivered through tactile arrays 3-electrotactile interface on the tongue 4-allow brain to learn and interpert the info | P27: 26
B28: 10.1016/j.asej.2023.102387 | C28: An effective obstacle detection system using deep learning advantages to aid blind and visually impaired navigation | D28: 2024 | E28: Elsevier | F28: https://www.sciencedirect.com/science/article/pii/S2090447923002769?via%3Dihub | G28: Deep Learning Modified YOLOv5 Computer Vision Obstacle/Object Detection Indoor & Outdoor Environment Model optimization for deployment on embedded devices | H28: included | I28: Paper focus on obstacle detection for blind using YOLOv5 model it cover indoor andoutdoor objects and uses optimization method to make model lightweight | J28: Blind and visually impaired people have difficulty detecting obstacles and navigating safely in their surroundings. | K28: The paper proposes a modified YOLOv5-based obstacle detection system to detect objects/obstacles and provide information that can assist blind and visually impaired users during navigation | P28: 27
B29: 10.1109/JAS.2021.1004084 | C29: An RGB-D Camera Based Visual Positioning System for Assistive Navigation by a Robotic Navigation Aid | D29: 2021 | E29: IEEE | F29: https://www.ieee-jas.net/article/doi/10.1109/JAS.2021.1004084?pageType=en | G29: RGB-D Camera IMU Visual-Inertial Odometry (VIO) 6-DOF Pose Estimation Particle Filter Localization Indoor CAD/Floor Plans Path Planning & Obstacle Avoidance Real-time processing | H29: Included | I29: Because it focuses on assistiv navigation for impaired users and combine computer vision with RGB and real time navigation | J29: blind people need reliable navigation assistance in large indoor environments Existing mobility tools such as white canes and guide dogs do not provide electronic localization/navigation information | K29: The paper develops a real-time visual positioning system for a robotic navigation aid. It combines an RGB-D camera + IMU to estimate the device's 6-DOF pose, then uses a particle filter and indoor CAD floor-plan information to reduce localization error and support wayfinding | P29: 28
C30: duplicated | H30: Excluded | P30: 29
B31: X | C31: X | D31: X | E31: Taylor & Francis | F31: https://www.tandfonline.com/doi/epdf/10.1080/23311916.2025.2560974?needAccess=true | G31: X | H31: Excluded | I31: because paper published by taylor press that not included in our scope | J31: X | K31: X | P31: 30
B32: 10.1177/20552076251408522 | C32: Sensory-driven micro-interventions for improved health and wellbeing | D32: 2025 | E32: Sage | F32: https://journals.sagepub.com/home/dhj | G32: AI / Machine Learning IoT Wearable sensors Sensory devices & interfaces Real-time data collection and processing Sensory substitution Vibrotactile / haptic feedback Smartphones and connected devices Embedded sensors | H32: included | I32: included because paper support sensory substituation and hapitic feedback concept of super Brain it discusses technologies that convert environmental/visual information into tactile feedback for visually impaired users | J32: sensory technologies work separately there no simple system for continuously monitoring sensory changes and providing personalized help when needed | K32: The paper proposes using AI IoT wearable sensors and sensory devices to monitor sensory changes and provide personalized sensory training | P32: 31
B33: 10.1007/s42486-023-00136-7 | C33: A smart obstacle avoiding technology based on depth camera for blind and visually impaired people | D33: 2023 | E33: Springer Nature | F33: https://link.springer.com/article/10.1007/s42486-023-00136-7? | G33: Depth/RGB-D Camera — Intel RealSense D435i 3D Point Cloud L-PointPillars Deep Learning / Neural Network Depthwise Separable Convolution Attention Mechanism NVIDIA Jetson Xavier NX PyTorch + Python Text-to-Speech (TTS) Audio Feedback | H33: included | I33: Included because it uses a depth camera and AI-based obstacle detection to help blind and visually impaired people navigate safely outdoors | J33: impaired people difficult detecting and avoiding obstacles when traveling outdoors. Existing assistive devices have limited detection range and limited computing power | K33: The paper proposes a wearable system that uses a depth camera and L-PointPillars to detect obstacles in real time and gives audio information about the obstacle and its distance | P33: 32
B34: 10.1016/j.eswa.2023.121065 | C34: A data fusion framework based on heterogeneous information network embedding for trigger-action programming in IoT | D34: 2023 | E34: Elsevier | F34: https://www.sciencedirect.com/science/article/abs/pii/S0957417423015671?via%3Dihub | G34: IoT Artificial Intelligence of Things (NLP) Heterogeneous Information Network HIN Embedding Metagraph-guided Random Walk Skip-gram Multi-label Classification | H34: included | I34: there are too many trigger-action combinations that is difficult and time-consuming for users to create IoT recipes manually | K34: The paper proposes TAPFuser an IoT framework that uses NLP and HIN embedding to understand natural-language requests and automatically recommend suitable trigger-action recipe | P34: 33
B35: 10.1038/s41928-023-01074-z | C35: A skin-integrated multimodal haptic interface for immersive tactile feedback | D35: 2023 | E35: Nature | H35: included | J35: X | K35: X | P35: 34
B36: 10.1002/aisy.70450 | C36: Enhanced Monocular Depth Estimation Using ResNet Backbone and Multiscale Feature Decoding for Precise Object Distance Measurement | D36: 2026 | E36: Wiley | F36: https://www.nature.com/articles/s41928-023-01074-z | G36: Monocular RGB Camera Deep Learning ResNet-based Encoder–Decoder Multiscale Feature Decoding YOLOv8 Object Detection Monocular Depth Estimation Object Distance Estimation D-Far250 Dataset KITTI Dataset | H36: included | I36: because it uses deep learning and object detection and and monocular depth estimation to detect objects and measure their distance and that support obstacle detection and navigation in Super Brain | J36: Traditional depth systems often need expensive sensors such as LiDAR or stereo cameras while monocular systems can have difficulty estimating accurate distances especially for far objects. | K36: The paper proposes a deep-learning system that uses a single RGB camera with a ResNet-based model and YOLOv8 to estimate object depth and distance without LiDAR or stereo cameras | P36: 35
B37: https://doi.org/10.1016/j.patrec.2019.03.008 | C37: Enhancing perception for the visually impaired with deep learning techniques and low-cost wearable sensors | D37: 2020 | E37: Elsevier | F37: https://www.sciencedirect.com/science/article/abs/pii/S0167865519300881?via%3Dihub | G37: * Shirt-pocket miniature wireless RGB camera * smartphone , smart watch * Monocular Depth Estimation --> ResNet-50 backbone * Urban Object Detection:---> CNN detector : 7 urban obstacle classes * Spatial Discretization:---> Bins 3D space in front of the user into 9 sectors * Continuous 3-level intensity haptic feedback | H37: Included | I37: Deeplearning Techniques for Enhancing Perception for Visuall impaired | J37: * visually impaired people face the outdoor environment and connot detect teh distance of the obstacles * ETAs : Travel aids ---> relying on RGB camera , LIDAR are heavy , big , fail in sunlight , expensive | K37: * lightweigh , low cost , replace with physical depth sensors * monocular depth , couples with object dedector * descretizes 3d space , delivers continuous 3 intensity habtic vibration | P37: 36
A38: Abdalah | B38: https://doi.org/10.1016/j.neunet.2023.12.042 | C38: Bidirectional visual-tactile cross-modal generation using latent feature space flow model | D38: 2023 | E38: Elsevier | F38: https://www.sciencedirect.com/science/article/pii/S0893608023007499?via%3Dihub | G38: * Decoupled visual and tactile Variational Autoencoders * Conditional Flow Model * Contrastive Supervision: InfoNCE contrastive loss (CLIP-style) * Sensory Modalities & Datasets: Evaluated on Touch2Go and LMT multimodal datasets * Quantitative Results: Reaches SSIM | H38: Included | I38: artificial sensory substitution by translating 2D visual inputs into tactile representations | J38: * scale discrepancy ---> global scene geometry vs. localized tactile contact * heterogeneous gap ---> pixels vs. mechanical deformation/vibration * Prior cross-modal methods were strictly unidirectional or required training two separate, unstable GAN networks , leading to inconsistent representations and heavy computational cost. | K38: * A unified generative architecture that maps visual features and tactile signals into separate VAE latent spaces, connected by an invertible conditional flow model that bidirectionally translates visual scenes into realistic tactile representations with high semantic fidelity. | P38: 37
B39: https://ieeexplore.ieee.org/document/5165018 | C39: Wearable Obstacle Avoidance Electronic Travel Aids for Blind: A Survey | D39: 2010 | E39: IEEE | F39: https://ieeexplore.ieee.org/document/5165018 | G39: ------------------ | H39: Excluded | I39: Survey | J39: ------------------ | K39: ------------------ | P39: 38
B40: https://doi.org/10.1007/s11042-021-11287-z | C40: Design and development of an indoor navigation system using denoising autoencoder based convolutional neural network for visually impaired people | D40: 2021 | E40: Springer | F40: https://link.springer.com/article/10.1007/s11042-021-11287-z | G40: * DAECNN Architecture * Multi-Angle Visual Localization --> Classifies 12 discrete viewing angles * Evaluation & Dataset---> Trained on 11,190 indoor frames | H40: Included | I40: Vision-Based Indoor Navigation & Visual Localization | J40: * GPS satellite signals cannot penetrate indoor environments * Alternative indoor positioning technologies ----> expensive, power consumpsion * Camera images captured while walking suffer from heavy motion blur, camera shaking, | K40: * Implements the DAECNN pipeline ---> enoising autoencoder to strip noise and motion blur * user positioning accuracy without external infrastructure | P40: 39
...

Sheet Mohsen
B1: Paper's DOI | C1: Title | D1: Publication Year | E1: Publisher | F1: paper URL | G1: Technology | H1: Included or Excluded | I1: Reason for inclusivity | J1: Problem | K1: Solution | L1: Main Tag | M1: Another Tags | N1: Custom Numbering M-## | O1: Additionals Notes
A2: Mohsen | B2: x | H2: excluded | I2: unknown
B3: x | H3: excluded | I3: unknown
B4: x | H4: excluded | I4: unknown
B5: x | H5: excluded | I5: unknown
B6: x | H6: excluded | I6: unknown
B7: x | H7: excluded | I7: unknown
B8: 10.1109/ACCESS.2025.3548552 | C8: Sensory Substitution Device for Time Presentation: Spatial–Temporal Vibrotactile Encoding for Presenting Time on the Human Wrist | D8: `10-Mar-202 | E8: IEEE | F8: https://doi.org/10.1109/ACCESS.2025.3548552?utm_source=chatgpt.com | G8: Vibrotactile feedback, Arduino Mega (ATmega2560), vibration motors | H8: included | I8: Relevant to wearable haptic feedback and tactile information encoding. | J8: Communicating information through vibration patterns that users can understand accurately. | K8: A wrist-worn device that represents time using spatial and temporal vibration patterns. | L8: #wearable-tech | M8: #wearable-tech, #assistive-technology, #embedded-systems, #microcontroller, #accessibility, #visual-impairment | N8: M-01 | O8: The paper focuses on presenting time through vibration, not AI-based environmental perception or navigation.
B9: doi:10.1016/j.tics.2003.10.013 | C9: Sensory substitution and the human–machine interface | D9: 37967 | H9: excluded | I9: date
B10: x | C10: Obstacle Detection, Depth Estimation And Warning System For Visually Impaired People | H10: excluded | I10: date
B11: https://doi.org/10.1007/s13042-023-01887-6 | C11: Structured deep learning based object‐specific distance estimation from a monocular image | D11: 45088 | E11: Springer | F11: https://link.springer.com/article/10.1007/s13042-023-01887-6 | H11: included | N11: M-02 | O11: CAN'T Reach the pdf yet
B12: 10.1109/TOH.2021.3077619 | C12: Survey of Pseudo-Haptics: Haptic Feedback Design and Application Proposals | D12: OCTOBER-DECEMBER 2021 | E12: IEEE | H12: excluded | I12: survey
B13: 10.1177/10711813251360706 | C13: Navigation Assistance Via Haptic Technology for Blind or Low-Vision Users: A Scoping Review | D13: 45866 | E13: SAGE | F13: https://journals.sagepub.com/doi/10.1177/10711813251360706 | G13: Review paper (Has No one technology) | H13: included | I13: Directly focuses on haptic and tactile technologies used to help blind or low-vision users navigate and receive directional guidance or obstacle warnings. | J13: Same Our Problem | K13: Review and evaluate haptic navigation approaches that communicate directions and obstacles through vibration, skin-stretch, or force feedback, sometimes combined with audio feedback. | L13: #assistive-technology | M13: #wearable-tech, #visual-impairment, #accessibility, #embedded-systems | N13: M-03 | O13: Exactly like what we want to do (Very Important) --- this paper mention also some papers talks about sound solutions not only haptic
A14: Mohsen | B14: https://papers.ssrn.com/sol3/papers.cfm?abstract_id=4989285 10.1109/TASE.2020.2971713 | C14: Toward Image-to-Tactile Cross-Modal Perception for Visually Impaired People | D14: 44287 | E14: IEEE | F14: https://ieeexplore.ieee.org/abstract/document/9018269 | H14: included | N14: M-04 | O14: not peer reviewed (Need ask if this work or no)
B15: https://doi.org/10.1007/s12193-025-00452-5 | C15: Vis-Assist: computer vision and haptic feedback-based wearable assistive device for visually impaired | D15: 45800 | E15: Springer | F15: https://link.springer.com/article/10.1007/s12193-025-00452-5 | H15: included | N15: M-05 | O15: CAN'T Reach the pdf yet
B16: doi:10.1016/j.concog.2009.10.006 | C16: Visual experiences in the blind induced by an auditory sensory substitution device | D16: 40148 | E16: sciencedirect | F16: https://www.sciencedirect.com/science/article/abs/pii/S1053810009001718?via%3Dihub | H16: excluded | I16: date
B17: x | H17: excluded
B26: =IF(C26="","","PID-"&TEXT(ROW()-2,"0000"))
B27: =IF(C27="","","PID-"&TEXT(ROW()-2,"0000"))
B28: =IF(C28="","","PID-"&TEXT(ROW()-2,"0000"))
B30: 0 | C30: Need to look for these
B31: 1 | C31: https://hal.science/hal-01993932v1/document
B32: =IF(C32="","","PID-"&TEXT(ROW()-2,"0000"))
B33: =IF(C33="","","PID-"&TEXT(ROW()-2,"0000"))
B34: =IF(C34="","","PID-"&TEXT(ROW()-2,"0000"))
B35: =IF(C35="","","PID-"&TEXT(ROW()-2,"0000"))
B36: =IF(C36="","","PID-"&TEXT(ROW()-2,"0000"))
B37: =IF(C37="","","PID-"&TEXT(ROW()-2,"0000"))
B38: =IF(C38="","","PID-"&TEXT(ROW()-2,"0000"))
B39: =IF(C39="","","PID-"&TEXT(ROW()-2,"0000"))
B40: =IF(C40="","","PID-"&TEXT(ROW()-2,"0000"))
B41: =IF(C41="","","PID-"&TEXT(ROW()-2,"0000"))
B42: =IF(C42="","","PID-"&TEXT(ROW()-2,"0000"))
B43: =IF(C43="","","PID-"&TEXT(ROW()-2,"0000"))
... B84: =IF(C84="","","PID-"&TEXT(ROW()-2,"0000"))

Sheet Ahmed
B1: Paper's DOI | C1: Title | D1: Publication Year | E1: Publisher | F1: paper URL | G1: Technology | H1: Included or Excluded | I1: Reason for inclusivity | J1: Problem | K1: Solution | L1: Main Tags | M1: Another Tags
A2: David | B2: 10.1016/j.bcp.2025.116272 | C2: A quantitative assessment of EOG eye tracking during free viewing in sighted and in congenitally blind | D2: 2025 | E2: Elsevier | F2: https://www.sciencedirect.com/science/article/pii/S0006899325003555?via%3Dihub | G2: Electrooculography (EOG) Video-Based Eye Tracking SMI Eye-Tracking Glasses Smarting Mobile EEG g.HIamp Amplifier BioSemi EEG vEOG / hEOG Blink Detection Saccade Detection The vOICe | H2: included | J2: Limited exploration of EOG in naturalistic/free-viewing conditions Video-based tracking can fail in blind individuals due to pupil abnormalities or eyelid control Need to detect eye movements without visual fixation | K2: EOG-based detection of blinks and saccades Comparison with video-based eye tracking Testing under light, darkness, eyes-closed, and congenital blindness Demonstrated that EOG can detect eye movements in blind participants
B3: 10.1016/j.neuroimage.2025.121652 | C3: Long-term visual-to-tactile stimulation induces functional reorganization of thalamic pathways to achieve visual perception | D3: 2025 | E3: Elsevier | F3: https://www.sciencedirect.com/science/article/pii/S105381192500655X?via%3Dihub | G3: Sensory Substitution Device (SSD) Visual-to-Tactile Conversion Tactile Stimulation Resting-State fMRI Functional Connectivity Analysis Thalamic/Occipital Brain Imaging | H3: included | J3: Limited understanding of how long-term tactile sensory substitution produces visual perception. Unclear how the brain reorganizes its pathways during prolonged SSD use. | K3: Long-term visual-to-tactile stimulation/training. Investigation of changes in thalamic–occipital connectivity to understand the neural mechanism.
B4: 10.1016/j.neuroimage.2021.118029 | C4: Topographic maps and neural tuning for sensory substitution dimensions learned in adulthood in a congenital blind subject | D4: 2021 | E4: Elsevier | F4: https://www.sciencedirect.com/science/article/pii/S1053811921003062?via%3Dihub | G4: Auditory Sensory Substitution Device 2D Auditory Soundscape Pitch Encoding Temporal Encoding Population Receptive Field Mapping fMRI | H4: included | J4: How the adult brain represents newly learned sensory dimensions in a person who is congenitally blind. | K4: Convert spatial information into auditory dimensions. Train the participant to interpret the auditory representation. Analyze the resulting neural maps and tuning.
B5: 10.1016/j.neuroimage.2024.120621 | C5: Visual Mental Imagery and Neural Dynamics of Sensory Substitution in the Blindfolded Subjects | D5: 2024 | E5: Elsevier | F5: https://www.sciencedirect.com/science/article/pii/S1053811924001162?via%3Dihub | G5: Auditory Sensory Substitution Visual-to-Auditory Encoding Soundscape Stimuli Functional MRI Dynamic Causal Modeling (DCM) Visual Mental Imagery | H5: included | J5: How sensory-substitution information is processed by the brain. Whether auditory sensory substitution can engage visual mental imagery. | K5: Train subjects to interpret auditory representations of visual shapes. Use neuroimaging and DCM to analyze the resulting brain-network dynamics.
B6: 10.1177/0145482X19842491 | C6: A Haptic Navigation Aid for Individuals with Visual Impairments: Indoor and Outdoor Feasibility Evaluations of the LaserNavigator | D6: 2019 | E6: SAGE Publications | F6: https://journals.sagepub.com/doi/10.1177/0145482X19842491 | G6: Laser Rangefinder Haptic Feedback Vibrating Actuator Handheld Device Virtual White Cane Variable Virtual Cane Length | H6: included | J6: Conventional white canes have a limited detection range. | K6: Use a laser rangefinder to detect objects beyond normal cane range. Convert measured distance into haptic feedback.
B7: 10.5220/0006617505550562 | C7: Wearable RGB Camera-based Navigation System for the Visually Impaired | D7: 2018 | E7: SciTePress | F7: https://www.scitepress.org/PublishedPapers/2018/66175/ | H7: Excluded | I7: Published by SciTePress
B8: 10.1609/aaai.v37i2.25233 | C8: BEVDepth: Acquisition of Reliable Depth for Multi-View 3D Object Detection | D8: 2023 | E8: AAAI | F8: https://ojs.aaai.org/index.php/AAAI/article/view/25233 | H8: Excluded | I8: Because it falls in a different feild of study and is published by AAAI
B9: 10.1109/EMBC.2013.6611022 | C9: Electrotactile vision substitution for 3D trajectory following | D9: 2013 | E9: IEEE | F9: https://ieeexplore.ieee.org/document/6611022 | H9: Excluded | I9: Published in 2013 and The linked IEEE document does not appear to correspond to the assistive-vision/navigation research needed for your review
B10: 10.1109/EIT51626.2021.9491913 | C10: Visually Impaired Indoor Navigation using YOLO Based Object Recognition, Monocular Depth Estimation and Binaural Sounds | D10: 2021 | E10: IEEE | F10: https://ieeexplore.ieee.org/document/9491913 | G10: Monocular RGB Camera Deep Learning ResNet-50 Backbone Encoder–Decoder Network YOLOv8 Object Detection Monocular Depth Estimation Object Distance Estimation D-Far250 Dataset KITTI Dataset Binaural/Spatial Audio HRTF | H10: included | J10: Difficulty detecting objects and understanding their distance and spatial position during indoor navigation. | K10: YOLO detects objects. Monocular depth estimation estimates object distance. Spatial information is converted into binaural audio. Audio provides directional and distance information to the user.
B11: 10.1109/TITS.2022.3161141 | C11: Trans4Trans: Efficient Transformer for Transparent Object and Semantic Scene Segmentation in Real-World Navigation Assistance | D11: 2021 | E11: arXiv | F11: https://ieeexplore.ieee.org/document/9743965 | G11: RGB-D Camera Portable GPU Trans4Trans Transformer Transformer Parsing Module (TPM) Semantic Segmentation Transparent Object Segmentation Depth Information Bone-Conduction Earphone | H11: included | J11: Transparent objects such as glass doors and glass walls can be incorrectly interpreted as free/walkable space. | K11: Detect transparent objects separately. Combine transparent-object segmentation with semantic segmentation and depth information. Provide navigation feedback to the visually impaired user.
B12: 10.1109/TOH.2021.3138590 | C12: In-Device Feedback in Immersive Head-Mounted Displays for Distance Perception During Teleoperation of Unmanned Ground Vehicles | D12: 2022 | E12: arXiv | F12: https://ieeexplore.ieee.org/document/9664257 | H12: Excluded | I12: Different feild of study (The actual application is remote control of unmanned ground vehicles0
B13: 10.48550/arXiv.2201.04453 | C13: Obstacle Avoidance for Blind People Using a 3D Camera and a Haptic Feedback Sleeve | D13: 2022 | E13: arXiv / CoRR | F13: https://arxiv.org/abs/2201.04453 | G13: Intel RealSense D415 3D Camera 3D Point Cloud Depth Mapping AAEON Up Board 5×5 Haptic Feedback Sleeve Vibration Motor Array Spatial Depth-to-Haptic Mapping 3D-Printed Glasses | H13: included | J13: Limited obstacle detection range using conventional aids. Difficulty providing multidimensional information about obstacles. Some existing approaches depend on lighting conditions. | K13: Capture 3D depth information using the RealSense camera. Convert the depth map into a 5×5 spatial representation. Map each region to a corresponding vibration motor. Use vibration intensity to communicate obstacle distance.
A14: salma | B14: 10.1080/23311916.2025.2560974 | C14: An assistive haptic-based obstacle avoidance system for individuals with profound visual impairment | D14: 2025 | E14: Taylor & Francis | F14: https://www.tandfonline.com/doi/full/10.1080/23311916.2025.2560974 | G14: X | H14: Excluded | I14: because paper published by taylor that not included in our scope | J14: X | K14: X
B15: https://doi.org/10.1002/aisy.70450Digital Object Identifier (DOI) | C15: Enhanced Monocular Depth Estimation Using ResNet Backbone and Multiscale Feature Decoding for Precise Object Distance Measurement | D15: 2026 | E15: Wiley | F15: https://advanced.onlinelibrary.wiley.com/doi/10.1002/aisy.70450 | H15: included
C16: Duplicated | H16: Execlauded
C17: Sight Guide: A Wearable Assistive Perception and Navigation System for the Vision Assistance Race in the Cybathlon 2024 | D17: 2025 | E17: Arixiv | H17: Excluded
B18: 10.1109/ICRA40945.2020.9196782 | C18: A Visual Positioning System for Indoor Blind Navigation | D18: 2020 | E18: IEEE | F18: https://www.researchgate.net/publication/339725908_A_Visual_Positioning_System_for_Indoor_Blind_Navigation | H18: included
B19: 10.1109/ACCESS.2023.3244073 | C19: A Survey on Outdoor Navigation Applications for People With Visual Impairments | D19: 2023 | E19: IEEE | F19: https://ieeexplore.ieee.org/document/10041898 | H19: included
B20: https://doi.org/10.1016/j.eswa.2023.121065 | C20: A data fusion framework based on heterogeneous information network embedding for trigger-action programming in IoT | D20: 2023 | E20: Elsevier | F20: https://www.sciencedirect.com/science/article/abs/pii/S0957417423015671?via%3Dihub | H20: included
B21: https://doi.org/10.48550/arXiv.2511.10026 | C21: Grating haptic perception through touchscreen: Sighted vs. Visually Impaired | D21: 2026 | E21: arXiv | F21: https://arxiv.org/abs/2511.10026v3 | G21: X | H21: Excluded | I21: because paper published by arix that not included in our scope | J21: X | K21: X
B22: https://doi.org/10.1007/s42486-023-00136-7 | C22: A smart obstacle avoiding technology based on depth camera for blind and visually impaired people (Commentry) | D22: 2023 | E22: Springer | F22: https://link.springer.com/article/10.1007/s42486-023-00136-7 | H22: Excluded
B23: 10.1177/20552076251408522 | C23: Sensory-driven micro-interventions for improved health and wellbeing | D23: 2025 | E23: Sage | F23: https://journals.sagepub.com/doi/10.1177/20552076251408522 | H23: included
H25: Excluded
A26: Taha | B26: 10.3233/APC210058 | C26: A Robotic Assisted System Using Deep Learning for Navigation and Reading IoT Based Home Automation for Visually Impaired | D26: 2021 | E26: IOS Press | F26: https://ebooks.iospress.nl/doi/10.3233/APC210058 | G26: X | H26: Excluded | I26: because paper published by IOS press that not included in our scope | J26: X | K26: X
B27: 10.1196/annals.1305.006 | C27: Tactile Sensory Substitution Studies | D27: 2004 | E27: Wiley | F27: https://nyaspubs.onlinelibrary.wiley.com/doi/epdf/10.1196/annals.1305.006 | G27: camera - Sensory Substitution - Tongue Electrotactile Interface - Vibrotactile Stimulation | H27: included | I27: The paper is included because it helps blind users by explaining sensory substitution by info from camera converted into tactile information that brain can learn to understand | J27: problem is to how to provide a visiual info to blind peoples by using tactile stimulation the chalenge is to create an effective brain -machine interface(BMI) | K27: the paper uses: 1-sensory substitution system : converts visual info from a camera into tactile (electrotactile stimulation) 2-stimulation is delivered through tactile arrays 3-electrotactile interface on the tongue 4-allow brain to learn and interpert the info
B28: 10.1016/j.asej.2023.102387 | C28: An effective obstacle detection system using deep learning advantages to aid blind and visually impaired navigation | D28: 2024 | E28: Elsevier | F28: https://www.sciencedirect.com/science/article/pii/S2090447923002769?via%3Dihub | G28: Deep Learning Modified YOLOv5 Computer Vision Obstacle/Object Detection Indoor & Outdoor Environment Model optimization for deployment on embedded devices | H28: included | I28: Paper focus on obstacle detection for blind using YOLOv5 model it cover indoor andoutdoor objects and uses optimization method to make model lightweight | J28: Blind and visually impaired people have difficulty detecting obstacles and navigating safely in their surroundings. | K28: The paper proposes a modified YOLOv5-based obstacle detection system to detect objects/obstacles and provide information that can assist blind and visually impaired users during navigation
B29: 10.1109/JAS.2021.1004084 | C29: An RGB-D Camera Based Visual Positioning System for Assistive Navigation by a Robotic Navigation Aid | D29: 2021 | E29: IEEE | F29: https://www.ieee-jas.net/article/doi/10.1109/JAS.2021.1004084?pageType=en | G29: RGB-D Camera IMU Visual-Inertial Odometry (VIO) 6-DOF Pose Estimation Particle Filter Localization Indoor CAD/Floor Plans Path Planning & Obstacle Avoidance Real-time processing | H29: Included | I29: Because it focuses on assistiv navigation for impaired users and combine computer vision with RGB and real time navigation | J29: blind people need reliable navigation assistance in large indoor environments Existing mobility tools such as white canes and guide dogs do not provide electronic localization/navigation information | K29: The paper develops a real-time visual positioning system for a robotic navigation aid. It combines an RGB-D camera + IMU to estimate the device's 6-DOF pose, then uses a particle filter and indoor CAD floor-plan information to reduce localization error and support wayfinding
C30: duplicated | H30: Excluded
B31: X | C31: X | D31: X | E31: Taylor & Francis | F31: https://www.tandfonline.com/doi/epdf/10.1080/23311916.2025.2560974?needAccess=true | G31: X | H31: Excluded | I31: because paper published by taylor press that not included in our scope | J31: X | K31: X
B32: 10.1177/20552076251408522 | C32: Sensory-driven micro-interventions for improved health and wellbeing | D32: 2025 | E32: Sage | F32: https://journals.sagepub.com/home/dhj | G32: AI / Machine Learning IoT Wearable sensors Sensory devices & interfaces Real-time data collection and processing Sensory substitution Vibrotactile / haptic feedback Smartphones and connected devices Embedded sensors | H32: included | I32: included because paper support sensory substituation and hapitic feedback concept of super Brain it discusses technologies that convert environmental/visual information into tactile feedback for visually impaired users | J32: sensory technologies work separately there no simple system for continuously monitoring sensory changes and providing personalized help when needed | K32: The paper proposes using AI IoT wearable sensors and sensory devices to monitor sensory changes and provide personalized sensory training
B33: 10.1007/s42486-023-00136-7 | C33: A smart obstacle avoiding technology based on depth camera for blind and visually impaired people | D33: 2023 | E33: Springer Nature | F33: https://link.springer.com/article/10.1007/s42486-023-00136-7? | G33: Depth/RGB-D Camera — Intel RealSense D435i 3D Point Cloud L-PointPillars Deep Learning / Neural Network Depthwise Separable Convolution Attention Mechanism NVIDIA Jetson Xavier NX PyTorch + Python Text-to-Speech (TTS) Audio Feedback | H33: included | I33: Included because it uses a depth camera and AI-based obstacle detection to help blind and visually impaired people navigate safely outdoors | J33: impaired people difficult detecting and avoiding obstacles when traveling outdoors. Existing assistive devices have limited detection range and limited computing power | K33: The paper proposes a wearable system that uses a depth camera and L-PointPillars to detect obstacles in real time and gives audio information about the obstacle and its distance
B34: 10.1016/j.eswa.2023.121065 | C34: A data fusion framework based on heterogeneous information network embedding for trigger-action programming in IoT | D34: 2023 | E34: Elsevier | F34: https://www.sciencedirect.com/science/article/abs/pii/S0957417423015671?via%3Dihub | G34: IoT Artificial Intelligence of Things (NLP) Heterogeneous Information Network HIN Embedding Metagraph-guided Random Walk Skip-gram Multi-label Classification | H34: included | I34: there are too many trigger-action combinations that is difficult and time-consuming for users to create IoT recipes manually | K34: The paper proposes TAPFuser an IoT framework that uses NLP and HIN embedding to understand natural-language requests and automatically recommend suitable trigger-action recipe
B35: 10.1038/s41928-023-01074-z | C35: A skin-integrated multimodal haptic interface for immersive tactile feedback | D35: 2023 | E35: Nature | H35: included | J35: X | K35: X
B36: 10.1002/aisy.70450 | C36: Enhanced Monocular Depth Estimation Using ResNet Backbone and Multiscale Feature Decoding for Precise Object Distance Measurement | D36: 2026 | E36: Wiley | F36: https://www.nature.com/articles/s41928-023-01074-z | G36: Monocular RGB Camera Deep Learning ResNet-based Encoder–Decoder Multiscale Feature Decoding YOLOv8 Object Detection Monocular Depth Estimation Object Distance Estimation D-Far250 Dataset KITTI Dataset | H36: included | I36: because it uses deep learning and object detection and and monocular depth estimation to detect objects and measure their distance and that support obstacle detection and navigation in Super Brain | J36: Traditional depth systems often need expensive sensors such as LiDAR or stereo cameras while monocular systems can have difficulty estimating accurate distances especially for far objects. | K36: The paper proposes a deep-learning system that uses a single RGB camera with a ResNet-based model and YOLOv8 to estimate object depth and distance without LiDAR or stereo cameras
B37: https://doi.org/10.1016/j.patrec.2019.03.008 | C37: Enhancing perception for the visually impaired with deep learning techniques and low-cost wearable sensors | D37: 2020 | E37: Elsevier | F37: https://www.sciencedirect.com/science/article/abs/pii/S0167865519300881?via%3Dihub | G37: * Shirt-pocket miniature wireless RGB camera * smartphone , smart watch * Monocular Depth Estimation --> ResNet-50 backbone * Urban Object Detection:---> CNN detector : 7 urban obstacle classes * Spatial Discretization:---> Bins 3D space in front of the user into 9 sectors * Continuous 3-level intensity haptic feedback | H37: Included | I37: Deeplearning Techniques for Enhancing Perception for Visuall impaired | J37: * visually impaired people face the outdoor environment and connot detect teh distance of the obstacles * ETAs : Travel aids ---> relying on RGB camera , LIDAR are heavy , big , fail in sunlight , expensive | K37: * lightweigh , low cost , replace with physical depth sensors * monocular depth , couples with object dedector * descretizes 3d space , delivers continuous 3 intensity habtic vibration
A38: Abdalah | B38: https://doi.org/10.1016/j.neunet.2023.12.042 | C38: Bidirectional visual-tactile cross-modal generation using latent feature space flow model | D38: 2023 | E38: Elsevier | F38: https://www.sciencedirect.com/science/article/pii/S0893608023007499?via%3Dihub | G38: * Decoupled visual and tactile Variational Autoencoders * Conditional Flow Model * Contrastive Supervision: InfoNCE contrastive loss (CLIP-style) * Sensory Modalities & Datasets: Evaluated on Touch2Go and LMT multimodal datasets * Quantitative Results: Reaches SSIM | H38: Included | I38: artificial sensory substitution by translating 2D visual inputs into tactile representations | J38: * scale discrepancy ---> global scene geometry vs. localized tactile contact * heterogeneous gap ---> pixels vs. mechanical deformation/vibration * Prior cross-modal methods were strictly unidirectional or required training two separate, unstable GAN networks , leading to inconsistent representations and heavy computational cost. | K38: * A unified generative architecture that maps visual features and tactile signals into separate VAE latent spaces, connected by an invertible conditional flow model that bidirectionally translates visual scenes into realistic tactile representations with high semantic fidelity.
B39: https://ieeexplore.ieee.org/document/5165018 | C39: Wearable Obstacle Avoidance Electronic Travel Aids for Blind: A Survey | D39: 2010 | E39: IEEE | F39: https://ieeexplore.ieee.org/document/5165018 | G39: ------------------ | H39: Excluded | I39: Survey | J39: ------------------ | K39: ------------------
B40: https://doi.org/10.1007/s11042-021-11287-z | C40: Design and development of an indoor navigation system using denoising autoencoder based convolutional neural network for visually impaired people | D40: 2021 | E40: Springer | F40: https://link.springer.com/article/10.1007/s11042-021-11287-z | G40: * DAECNN Architecture * Multi-Angle Visual Localization --> Classifies 12 discrete viewing angles * Evaluation & Dataset---> Trained on 11,190 indoor frames | H40: Included | I40: Vision-Based Indoor Navigation & Visual Localization | J40: * GPS satellite signals cannot penetrate indoor environments * Alternative indoor positioning technologies ----> expensive, power consumpsion * Camera images captured while walking suffer from heavy motion blur, camera shaking, | K40: * Implements the DAECNN pipeline ---> enoising autoencoder to strip noise and motion blur * user positioning accuracy without external infrastructure
B41: https://doi.org/10.1007/s11042-023-16355-0 | C41: Development of a visual to audio and tactile substitution system for mobility and orientation of visually impaired people: a review | D41: 2023 | E41: Springer | F41: https://link.springer.com/article/10.1007/s11042-023-16355-0 | G41: * Sensory Substitution ---> visual-to-audio , visual-to-tactile * Reviews RGB cameras, depth sensors, ultrasonic transducers, and deep learning object/obstacle recognition models. | H41: Included | I41: Comprehensive Review of Visual-to-Tactile & Audio Sensory Substitution | J41: * white canes cannot detect elevated, head-height, or distant obstacles. * Existing assistive systems are non-adaptable, expensive, and heavily | K41: * prioritizing low-cost wearable tactile arrays that preserve hearing , simplify visual scene features into intuitive haptic patterns, and utilize structured user training protocols.
...

Sheet Fathy
B1: Paper's DOI | C1: Title | D1: Publication Year | E1: Publisher | F1: paper URL | G1: Technology | H1: Included or Excluded | I1: Reason for inclusivity | J1: Problem | K1: Solution | L1: Main Tags | M1: Another Tags
A2: David | B2: 10.1016/j.bcp.2025.116272 | C2: A quantitative assessment of EOG eye tracking during free viewing in sighted and in congenitally blind | D2: 2025 | E2: Elsevier | F2: https://www.sciencedirect.com/science/article/pii/S0006899325003555?via%3Dihub | G2: Electrooculography (EOG) Video-Based Eye Tracking SMI Eye-Tracking Glasses Smarting Mobile EEG g.HIamp Amplifier BioSemi EEG vEOG / hEOG Blink Detection Saccade Detection The vOICe | H2: included | J2: Limited exploration of EOG in naturalistic/free-viewing conditions Video-based tracking can fail in blind individuals due to pupil abnormalities or eyelid control Need to detect eye movements without visual fixation | K2: EOG-based detection of blinks and saccades Comparison with video-based eye tracking Testing under light, darkness, eyes-closed, and congenital blindness Demonstrated that EOG can detect eye movements in blind participants
B3: 10.1016/j.neuroimage.2025.121652 | C3: Long-term visual-to-tactile stimulation induces functional reorganization of thalamic pathways to achieve visual perception | D3: 2025 | E3: Elsevier | F3: https://www.sciencedirect.com/science/article/pii/S105381192500655X?via%3Dihub | G3: Sensory Substitution Device (SSD) Visual-to-Tactile Conversion Tactile Stimulation Resting-State fMRI Functional Connectivity Analysis Thalamic/Occipital Brain Imaging | H3: included | J3: Limited understanding of how long-term tactile sensory substitution produces visual perception. Unclear how the brain reorganizes its pathways during prolonged SSD use. | K3: Long-term visual-to-tactile stimulation/training. Investigation of changes in thalamic–occipital connectivity to understand the neural mechanism.
B4: 10.1016/j.neuroimage.2021.118029 | C4: Topographic maps and neural tuning for sensory substitution dimensions learned in adulthood in a congenital blind subject | D4: 2021 | E4: Elsevier | F4: https://www.sciencedirect.com/science/article/pii/S1053811921003062?via%3Dihub | G4: Auditory Sensory Substitution Device 2D Auditory Soundscape Pitch Encoding Temporal Encoding Population Receptive Field Mapping fMRI | H4: included | J4: How the adult brain represents newly learned sensory dimensions in a person who is congenitally blind. | K4: Convert spatial information into auditory dimensions. Train the participant to interpret the auditory representation. Analyze the resulting neural maps and tuning.
B5: 10.1016/j.neuroimage.2024.120621 | C5: Visual Mental Imagery and Neural Dynamics of Sensory Substitution in the Blindfolded Subjects | D5: 2024 | E5: Elsevier | F5: https://www.sciencedirect.com/science/article/pii/S1053811924001162?via%3Dihub | G5: Auditory Sensory Substitution Visual-to-Auditory Encoding Soundscape Stimuli Functional MRI Dynamic Causal Modeling (DCM) Visual Mental Imagery | H5: included | J5: How sensory-substitution information is processed by the brain. Whether auditory sensory substitution can engage visual mental imagery. | K5: Train subjects to interpret auditory representations of visual shapes. Use neuroimaging and DCM to analyze the resulting brain-network dynamics.
B6: 10.1177/0145482X19842491 | C6: A Haptic Navigation Aid for Individuals with Visual Impairments: Indoor and Outdoor Feasibility Evaluations of the LaserNavigator | D6: 2019 | E6: SAGE Publications | F6: https://journals.sagepub.com/doi/10.1177/0145482X19842491 | G6: Laser Rangefinder Haptic Feedback Vibrating Actuator Handheld Device Virtual White Cane Variable Virtual Cane Length | H6: included | J6: Conventional white canes have a limited detection range. | K6: Use a laser rangefinder to detect objects beyond normal cane range. Convert measured distance into haptic feedback.
B7: 10.5220/0006617505550562 | C7: Wearable RGB Camera-based Navigation System for the Visually Impaired | D7: 2018 | E7: SciTePress | F7: https://www.scitepress.org/PublishedPapers/2018/66175/ | H7: Excluded | I7: Published by SciTePress
B8: 10.1609/aaai.v37i2.25233 | C8: BEVDepth: Acquisition of Reliable Depth for Multi-View 3D Object Detection | D8: 2023 | E8: AAAI | F8: https://ojs.aaai.org/index.php/AAAI/article/view/25233 | H8: Excluded | I8: Because it falls in a different feild of study and is published by AAAI
B9: 10.1109/EMBC.2013.6611022 | C9: Electrotactile vision substitution for 3D trajectory following | D9: 2013 | E9: IEEE | F9: https://ieeexplore.ieee.org/document/6611022 | H9: Excluded | I9: Published in 2013 and The linked IEEE document does not appear to correspond to the assistive-vision/navigation research needed for your review
B10: 10.1109/EIT51626.2021.9491913 | C10: Visually Impaired Indoor Navigation using YOLO Based Object Recognition, Monocular Depth Estimation and Binaural Sounds | D10: 2021 | E10: IEEE | F10: https://ieeexplore.ieee.org/document/9491913 | G10: Monocular RGB Camera Deep Learning ResNet-50 Backbone Encoder–Decoder Network YOLOv8 Object Detection Monocular Depth Estimation Object Distance Estimation D-Far250 Dataset KITTI Dataset Binaural/Spatial Audio HRTF | H10: included | J10: Difficulty detecting objects and understanding their distance and spatial position during indoor navigation. | K10: YOLO detects objects. Monocular depth estimation estimates object distance. Spatial information is converted into binaural audio. Audio provides directional and distance information to the user.
B11: 10.1109/TITS.2022.3161141 | C11: Trans4Trans: Efficient Transformer for Transparent Object and Semantic Scene Segmentation in Real-World Navigation Assistance | D11: 2021 | E11: arXiv | F11: https://ieeexplore.ieee.org/document/9743965 | G11: RGB-D Camera Portable GPU Trans4Trans Transformer Transformer Parsing Module (TPM) Semantic Segmentation Transparent Object Segmentation Depth Information Bone-Conduction Earphone | H11: included | J11: Transparent objects such as glass doors and glass walls can be incorrectly interpreted as free/walkable space. | K11: Detect transparent objects separately. Combine transparent-object segmentation with semantic segmentation and depth information. Provide navigation feedback to the visually impaired user.
B12: 10.1109/TOH.2021.3138590 | C12: In-Device Feedback in Immersive Head-Mounted Displays for Distance Perception During Teleoperation of Unmanned Ground Vehicles | D12: 2022 | E12: arXiv | F12: https://ieeexplore.ieee.org/document/9664257 | H12: Excluded | I12: Different feild of study (The actual application is remote control of unmanned ground vehicles0
